Workbook

Sheet Form responses 1
A1: Timestamp | B1: Email address | C1: Which country are you affiliated to? (use Switzerland instead of CH) | D1: Did you or your country contribute to one of the deliverables (or a closely related one)? (Indicate all, we will then follow up) (April 2020 until October 2022) | E1: Did you or your country contribute to one of the MoU objectives (or a closely related one)? (Indicate all, we will then follow up) (April 20 to Oct 22) | F1: Were you (co-) author of a COST related publication (incl. submitted pre-prints (e.g. arxiv.org))? | G1: Were you or your country involved in other projects resulting from Action activities? (If yes, we will follow up with more details later) | H1: Were you or your country involved in other outputs/ achievements resulting from Action activities? (e.g. a patent, standards, white paper) | I1: Did you create any other impact related to COST FinAI? | J1: Did you contribute to activities that are advancing the careers, skills and network of researchers, including ECIs(for example: joint supervision of graduate and PhD students, research exchanges not funded by the Action, collaborations, Training Schools with ECTS accreditation, joint projects and jobs prospects). | K1: Did you participate in other dissemination activities? (E.g. participation to non-Action meetings, e.g. EU Parliament, meetings with policy makers, experts in the field, regional authorities.) | L1: Were you involved in any other activities undertaken to ensure exploitation (use, in particular in a commercial context) of the Action's achievements. | M1: Score | N1: Which working group do you belong to? | O1: Anything else you think is relevant to the COST report from April 20 to Oct 22? Please add any other achievements, outcomes, cooperations, etc. | P1: Were you involved in any proposals/ projects?
A2: 44752.81 | B2: lleshlleshaj@feut.edu.al | C2: Albania | D2: A discussion paper for possible approaches to building a statistically valid back-testing framework, Methodological discussion paper on the design of stress tests for the evaluation of AI and ML models under shifting financial conditions to improve the robustness of models | E2: Significantly improve the gender equality in the fields of the Action. | F2: No | H2: No | J2: No | K2: Yes | L2: No | M2: 0 | N2: WG 1 | P2: No
A3: 44756.976 | B3: eliona.gremi@uniel.edu.al | C3: Albania | D3: No | E3: Create an excellent network of researchers in Europe with lasting collaboration beyond the lifetime of the Action., Transfer knowledge in terms of expertise, scientific tools and human resources across the different disciplines and between academia and industry. | F3: No | H3: No | J3: No | K3: No | L3: Yes | M3: 0 | N3: WG 1, WG 2, WG 3 | P3: No
A4: 44772.589 | B4: tidjani.chemseddine@gmail.com | C4: Algeria | D4: No | E4: Disseminate to the public and share with regulators the results on investment product performance evaluation., Bridging the gap between practitioners from the finance industry, academics and regulators by setting up a common knowledge exchange platform., Transfer knowledge in terms of expertise, scientific tools and human resources across the different disciplines and between academia and industry. | F4: Yes | H4: No | J4: Yes | K4: Yes | L4: No | M4: 0 | N4: WG 2 | O4: Cost action can be considered as a resource for diverse human capacities from all over the world. Cost action can establish and reinforce collaborations between Europe and TCC countries. | P4: Yes
A5: 44736.475 | B5: ronald.hochreiter@wu.ac.at | C5: Austria | D5: Anything else useful for the COST Action, not mentioned below, An edited volume containing scientific achievements of the Action | E5: Anything else useful and related to the below topics, To develop blended approaches to evaluate innovative financial services and their providers, especially in the FinTech domain, building on Machine Learning methods, focussing on prediction (early warning) of operational fragility, fraudulent and illegal behaviour ranging from appropriation of loaned funds to money-laundering activities., The development of conceptual and methodological tools for establishing when blackbox models are admissible and, to the extent possible, making them more transparent and/or replacing them with interpretable and explainable models., To receive input from regulators and practitioners' communities and to validate results with regard to increasing transparency of artificial intelligence applications., Disseminate to the public and share with regulators the results on investment product performance evaluation., Create an excellent network of researchers in Europe with lasting collaboration beyond the lifetime of the Action., Bridging the gap between practitioners from the finance industry, academics and regulators by setting up a common knowledge exchange platform., Transfer knowledge in terms of expertise, scientific tools and human resources across the different disciplines and between academia and industry., Disseminate the results of the Action's activities to the scientific community, European institutions and to the general public. | F5: No | H5: No | J5: No | K5: Yes | L5: Yes | M5: 0 | N5: WG 1, WG 2, WG 3 | P5: Yes
A6: 44746.816 | B6: aivanisev@net.efzg.hr | C6: Croatia | D6: Anything else useful for the COST Action, not mentioned below | E6: Anything else useful and related to the below topics, Create an excellent network of researchers in Europe with lasting collaboration beyond the lifetime of the Action., Bridging the gap between practitioners from the finance industry, academics and regulators by setting up a common knowledge exchange platform., Disseminate the results of the Action's activities to the scientific community, European institutions and to the general public. | F6: No | H6: No | J6: No | K6: No | L6: No | M6: 0 | N6: WG 1, WG 3 | O6: Organisation of a conference related to COST FinAI topics of interest, which has served as a knowledge exchange platform between researchers, practitioners and regulators | P6: No
A7: 44796.414 | B7: svlahjeric@gmail.com | C7: Croatia | D7: Anything else useful for the COST Action, not mentioned below | E7: Create an excellent network of researchers in Europe with lasting collaboration beyond the lifetime of the Action., Bringing technological, quantitative and economic researchers together, to tackle future research that can only be done in an interdisciplinary setting, and getting actively involved in the blockchain and FinTech communities across Europe, to constantly monitor developments, get input and disseminate results., Transfer knowledge in terms of expertise, scientific tools and human resources across the different disciplines and between academia and industry. | F7: No | H7: No | J7: No | K7: Yes | L7: No | M7: 0 | N7: WG 2 | P7: No
A8: 44752.788 | B8: georgiou.i@unic.ac.cy | C8: Cyprus | D8: No | E8: No, Anything else useful and related to the below topics, Bringing technological, quantitative and economic researchers together, to tackle future research that can only be done in an interdisciplinary setting, and getting actively involved in the blockchain and FinTech communities across Europe, to constantly monitor developments, get input and disseminate results., Overcome the siloing of research topics by country and achieve geographical and demographical diversity, with special attention to COST Inclusiveness Target countries., Significantly improve the gender equality in the fields of the Action. | F8: No | H8: No | J8: No | K8: No | L8: No | M8: 0 | N8: WG 1 | P8: Yes
A9: 44736.427 | B9: petr.hajek@upce.cz | C9: Czech Republic | D9: Anything else useful for the COST Action, not mentioned below | E9: No | F9: No | H9: Yes | J9: Yes | K9: Yes | L9: No | M9: 0 | N9: WG 2 | P9: Yes
A10: 44796.432 | B10: luislore@ucm.es | C10: España | D10: A discussion paper for possible approaches to building a statistically valid back-testing framework | E10: Maximize the job opportunities for PhD students and Early Career Investigators., Disseminate the results of the Action's activities to the scientific community, European institutions and to the general public. | F10: Yes | H10: Yes | J10: Yes | K10: No | L10: No | M10: 0 | N10: WG 2 | P10: Yes
A11: 44736.803 | B11: laivi.laidroo@taltech.ee | C11: Estonia | D11: No | E11: No | F11: No | H11: No | J11: No | K11: Yes | L11: Yes | M11: 0 | N11: WG 1 | P11: No
A12: 44753.418 | B12: innar.liiv@taltech.ee | C12: Estonia | D12: Anything else useful for the COST Action, not mentioned below | E12: To develop blended approaches to evaluate innovative financial services and their providers, especially in the FinTech domain, building on Machine Learning methods, focussing on prediction (early warning) of operational fragility, fraudulent and illegal behaviour ranging from appropriation of loaned funds to money-laundering activities., The development of conceptual and methodological tools for establishing when blackbox models are admissible and, to the extent possible, making them more transparent and/or replacing them with interpretable and explainable models., To receive input from regulators and practitioners' communities and to validate results with regard to increasing transparency of artificial intelligence applications., Create an excellent network of researchers in Europe with lasting collaboration beyond the lifetime of the Action., Bringing technological, quantitative and economic researchers together, to tackle future research that can only be done in an interdisciplinary setting, and getting actively involved in the blockchain and FinTech communities across Europe, to constantly monitor developments, get input and disseminate results., Transfer knowledge in terms of expertise, scientific tools and human resources across the different disciplines and between academia and industry., Overcome the siloing of research topics by country and achieve geographical and demographical diversity, with special attention to COST Inclusiveness Target countries., Disseminate the results of the Action's activities to the scientific community, European institutions and to the general public. | F12: Yes | H12: No | J12: No | K12: Yes | L12: Yes | M12: 0 | N12: WG 3 | O12: Published a book, COST action is mentioned: https://link.springer.com/book/10.1007/978-981-16-2418-6 | P12: No
A13: 44735.473 | B13: roman.matkovskyy@rennes-sb.com | C13: France | D13: A database which contains data on crowdfunding/P2P platform features useful for rating platform integrity and to predict fraud, A position paper and roadmap on mitigating risks connected with the increased use of digital assets | E13: Bringing technological, quantitative and economic researchers together, to tackle future research that can only be done in an interdisciplinary setting, and getting actively involved in the blockchain and FinTech communities across Europe, to constantly monitor developments, get input and disseminate results., Transfer knowledge in terms of expertise, scientific tools and human resources across the different disciplines and between academia and industry., Disseminate the results of the Action's activities to the scientific community, European institutions and to the general public. | F13: Yes | H13: No | I13: Yes | J13: Yes | K13: Yes | L13: No | M13: 0 | N13: WG 1, WG 2 | O13: rather explanation of the previous points: databases on KIVA Paper: Jalan, A., Matkovskyy, R., and Poti, V. (2022). "Shall the winning last? A study of recent bubbles and persistence." Finance Research Letters 45, 102162 Bringing technological, quantitative and economic researchers... and dissemination : the cryptocurrency investment conference jointly with WG1 meeting at Rennes School of business, April 2022 Transfer knowledge in terms of expertise...: Can I put a round table and a panel on crypto and DeFi at AFFI conference in May 2022, Saint Malo? Other : contribution to the network extension, mentioning our COST Actions in different meetings; joint supervision of a PhD student,
A14: 44749.087 | B14: elias.tsigaridas@inria.fr | C14: France | D14: A database which contains pre-ICO documentation and post-ICO performance (ROI and, A database which contains data on crowdfunding/P2P platform features useful for rating platform integrity and to predict fraud, Report on good examples and best practices for a transparent finance industry with guidelines to improve transparency, An internal database of collected (scraped) financial time series from exchanges and regional consolidation platforms optimised for accessibility to all partners, Key software (codes, packages) developed by each of the Working Groups in line with their objectives | E14: Anything else useful and related to the below topics, To develop blended approaches to evaluate innovative financial services and their providers, especially in the FinTech domain, building on Machine Learning methods, focussing on prediction (early warning) of operational fragility, fraudulent and illegal behaviour ranging from appropriation of loaned funds to money-laundering activities., The development of conceptual and methodological tools for establishing when blackbox models are admissible and, to the extent possible, making them more transparent and/or replacing them with interpretable and explainable models., Pruning and improvement of the vast array of performance attribution models by contributing to the development of methodologies for reducing the false discovery rate in financial research and applied financial investment management., Transfer knowledge in terms of expertise, scientific tools and human resources across the different disciplines and between academia and industry., Establish an inclusive community of researchers on methodological and technological themes in Machine Learning and Artificial Intelligence, to promote Early Career Investigators and increase their visibility., Maximize the job opportunities for PhD students and Early Career Investigators., Disseminate the results of the Action's activities to the scientific community, European institutions and to the general public., Significantly improve the gender equality in the fields of the Action. | F14: Yes | H14: Yes | J14: Yes | K14: No | L14: Yes | M14: 0 | N14: WG 1 | P14: Yes
A15: 44736.417 | B15: haerdle@hu-berlin.de | C15: Germany | D15: Anything else useful for the COST Action, not mentioned below, A database which contains pre-ICO documentation and post-ICO performance (ROI and, Discussion papers (DP) on the methodology for evaluating/rating ICOs and crowdfunding/P2P platforms and for detection/early warning about fraud/illegal behaviour with emphasis on the application of AI tools, A position paper and roadmap on mitigating risks connected with the increased use of digital assets, A discussion paper for possible approaches to building a statistically valid back-testing framework, Position papers, aimed at regulators and policy-makers, on methodology (with examples of formal criteria) for testing AI techniques in real-time, An internal database of collected (scraped) financial time series from exchanges and regional consolidation platforms optimised for accessibility to all partners, Methodological discussion papers on AI models to generate “failed trials” of investment product producers and on quantitative strategies with the usage of the promising field of network data analysis exchanges and regional consolidation platforms optimised for accessibility to all partners, Key software (codes, packages) developed by each of the Working Groups in line with their objectives, Handbook and/or wiki page describing potential approaches to tackle risk management issues related to blockchain assets and crowdfunding/P2P lending, An edited volume containing scientific achievements of the Action | E15: Anything else useful and related to the below topics, The development of conceptual and methodological tools for establishing when blackbox models are admissible and, to the extent possible, making them more transparent and/or replacing them with interpretable and explainable models., To receive input from regulators and practitioners' communities and to validate results with regard to increasing transparency of artificial intelligence applications., Pruning and improvement of the vast array of performance attribution models by contributing to the development of methodologies for reducing the false discovery rate in financial research and applied financial investment management., Disseminate to the public and share with regulators the results on investment product performance evaluation., Creation of the first European platform comparing the out-of-sample performance of banks' investment products, insurance-linked investment products and asset management products available to the general public., Create an excellent network of researchers in Europe with lasting collaboration beyond the lifetime of the Action., Bringing technological, quantitative and economic researchers together, to tackle future research that can only be done in an interdisciplinary setting, and getting actively involved in the blockchain and FinTech communities across Europe, to constantly monitor developments, get input and disseminate results., Transfer knowledge in terms of expertise, scientific tools and human resources across the different disciplines and between academia and industry., Overcome the siloing of research topics by country and achieve geographical and demographical diversity, with special attention to COST Inclusiveness Target countries., Maximize the job opportunities for PhD students and Early Career Investigators., Disseminate the results of the Action's activities to the scientific community, European institutions and to the general public., Significantly improve the gender equality in the fields of the Action. | F15: Yes | H15: Yes | J15: Yes | K15: Yes | L15: Yes | M15: 0 | N15: WG 1 | P15: Yes
A16: 44748.498 | B16: allapetukhina@icloud.com | C16: Germany | D16: Anything else useful for the COST Action, not mentioned below | E16: Create an excellent network of researchers in Europe with lasting collaboration beyond the lifetime of the Action., Bringing technological, quantitative and economic researchers together, to tackle future research that can only be done in an interdisciplinary setting, and getting actively involved in the blockchain and FinTech communities across Europe, to constantly monitor developments, get input and disseminate results., Bridging the gap between practitioners from the finance industry, academics and regulators by setting up a common knowledge exchange platform., Maximize the job opportunities for PhD students and Early Career Investigators., Significantly improve the gender equality in the fields of the Action. | F16: Yes | H16: No | J16: No | K16: Yes | L16: No | M16: 0 | N16: WG 1 | O16: Germany (Härdle)&Romania(D Pele, V Strat): Quantinar start - P2P knowledge platform supported by FinAI | P16: Yes
A17: 44729.578 | B17: veniarakelian@yahoo.com | C17: Greece | D17: A discussion paper for possible approaches to building a statistically valid back-testing framework, Report on good examples and best practices for a transparent finance industry with guidelines to improve transparency | E17: To develop blended approaches to evaluate innovative financial services and their providers, especially in the FinTech domain, building on Machine Learning methods, focussing on prediction (early warning) of operational fragility, fraudulent and illegal behaviour ranging from appropriation of loaned funds to money-laundering activities., The development of conceptual and methodological tools for establishing when blackbox models are admissible and, to the extent possible, making them more transparent and/or replacing them with interpretable and explainable models., To receive input from regulators and practitioners' communities and to validate results with regard to increasing transparency of artificial intelligence applications., Create an excellent network of researchers in Europe with lasting collaboration beyond the lifetime of the Action. | F17: Yes | G17: No | H17: Yes | I17: Yes | J17: Yes | K17: Yes | L17: No | M17: 0 | N17: WG 3
A18: 44749.723 | B18: tolis.chal@gmail.com | C18: Greece | D18: A position paper and roadmap on mitigating risks connected with the increased use of digital assets, Methodological discussion paper on the design of stress tests for the evaluation of AI and ML models under shifting financial conditions to improve the robustness of models | E18: Overcome the siloing of research topics by country and achieve geographical and demographical diversity, with special attention to COST Inclusiveness Target countries., Prepare competitive European researchers for a fruitful career in an international environment through intensive use of Short Term Scientific Missions (STSM) and joint educational programs with industrial partners., Maximize the job opportunities for PhD students and Early Career Investigators. | F18: No | H18: No | J18: No | K18: Yes | L18: No | M18: 0 | N18: WG 1, WG 3 | P18: No
A19: 44809.467 | B19: veniarakelian@yahoo.com | C19: Greece | D19: Discussion papers (DP) on the methodology for evaluating/rating ICOs and crowdfunding/P2P platforms and for detection/early warning about fraud/illegal behaviour with emphasis on the application of AI tools, Methodological discussion paper on the design of stress tests for the evaluation of AI and ML models under shifting financial conditions to improve the robustness of models, Key software (codes, packages) developed by each of the Working Groups in line with their objectives | E19: To develop blended approaches to evaluate innovative financial services and their providers, especially in the FinTech domain, building on Machine Learning methods, focussing on prediction (early warning) of operational fragility, fraudulent and illegal behaviour ranging from appropriation of loaned funds to money-laundering activities., The development of conceptual and methodological tools for establishing when blackbox models are admissible and, to the extent possible, making them more transparent and/or replacing them with interpretable and explainable models., To receive input from regulators and practitioners' communities and to validate results with regard to increasing transparency of artificial intelligence applications., Pruning and improvement of the vast array of performance attribution models by contributing to the development of methodologies for reducing the false discovery rate in financial research and applied financial investment management., Disseminate to the public and share with regulators the results on investment product performance evaluation., Create an excellent network of researchers in Europe with lasting collaboration beyond the lifetime of the Action., Bringing technological, quantitative and economic researchers together, to tackle future research that can only be done in an interdisciplinary setting, and getting actively involved in the blockchain and FinTech communities across Europe, to constantly monitor developments, get input and disseminate results., Bridging the gap between practitioners from the finance industry, academics and regulators by setting up a common knowledge exchange platform., Transfer knowledge in terms of expertise, scientific tools and human resources across the different disciplines and between academia and industry., Establish an inclusive community of researchers on methodological and technological themes in Machine Learning and Artificial Intelligence, to promote Early Career Investigators and increase their visibility., Overcome the siloing of research topics by country and achieve geographical and demographical diversity, with special attention to COST Inclusiveness Target countries., Prepare competitive European researchers for a fruitful career in an international environment through intensive use of Short Term Scientific Missions (STSM) and joint educational programs with industrial partners., Maximize the job opportunities for PhD students and Early Career Investigators., Disseminate the results of the Action's activities to the scientific community, European institutions and to the general public. | F19: Yes | H19: No | J19: Yes | K19: Yes | L19: Yes | M19: 0 | N19: WG 3 | O19: Close collaboration with Currency Research https://www.linkedin.com/company/currencyresearch/ | P19: Yes
A20: 44760.568 | B20: trimborn.econometrics@gmail.com | C20: Hong Kong | D20: Anything else useful for the COST Action, not mentioned below, Key software (codes, packages) developed by each of the Working Groups in line with their objectives | E20: Anything else useful and related to the below topics, To develop blended approaches to evaluate innovative financial services and their providers, especially in the FinTech domain, building on Machine Learning methods, focussing on prediction (early warning) of operational fragility, fraudulent and illegal behaviour ranging from appropriation of loaned funds to money-laundering activities., Create an excellent network of researchers in Europe with lasting collaboration beyond the lifetime of the Action. | F20: No | H20: No | J20: No | K20: No | L20: Yes | M20: 0 | N20: WG 1, WG 2, WG 3 | P20: No
A21: 44752.826 | B21: molnarba@inf.elte.hu | C21: Hungary | D21: Anything else useful for the COST Action, not mentioned below | E21: The development of conceptual and methodological tools for establishing when blackbox models are admissible and, to the extent possible, making them more transparent and/or replacing them with interpretable and explainable models., Bridging the gap between practitioners from the finance industry, academics and regulators by setting up a common knowledge exchange platform., Significantly improve the gender equality in the fields of the Action. | F21: Yes | H21: No | J21: Yes | K21: Yes | L21: Yes | M21: 0 | N21: WG 1, WG 2, WG 3 | P21: Yes
A22: 44796.434 | B22: molnarba@inf.elte.hu | C22: Hungary | D22: Anything else useful for the COST Action, not mentioned below | E22: To receive input from regulators and practitioners' communities and to validate results with regard to increasing transparency of artificial intelligence applications., Disseminate to the public and share with regulators the results on investment product performance evaluation., Transfer knowledge in terms of expertise, scientific tools and human resources across the different disciplines and between academia and industry., Establish an inclusive community of researchers on methodological and technological themes in Machine Learning and Artificial Intelligence, to promote Early Career Investigators and increase their visibility., Maximize the job opportunities for PhD students and Early Career Investigators., Disseminate the results of the Action's activities to the scientific community, European institutions and to the general public., Significantly improve the gender equality in the fields of the Action. | F22: Yes | H22: No | J22: Yes | K22: Yes | L22: Yes | M22: 0 | N22: WG 1, WG 2, WG 3 | P22: Yes
A23: 44737.731 | B23: rupelnargunam25@gmail.com | C23: India | D23: A discussion paper on market risk modeling, analysis and management, contributing to the methodological discussion section on risk measures and time series approaches used to obtain forecasts of risk measures. | E23: Anything else useful and related to the below topics | F23: Yes | H23: No | J23: No | K23: No | L23: No | M23: 0 | N23: WG 1 | O23: Presented research paper in Women in Fintech Conference organized by Fintech and Artificial Intelligence in Finance and European Cooperation in Science and Technology (COST), during 22nd - 23rd September 2021. | P23: No
A24: 44744.826 | B24: valerio.poti@ucd.ie | C24: Ireland | D24: A discussion paper for possible approaches to building a statistically valid back-testing framework, Methodological discussion paper on the design of stress tests for the evaluation of AI and ML models under shifting financial conditions to improve the robustness of models, Key software (codes, packages) developed by each of the Working Groups in line with their objectives | E24: To receive input from regulators and practitioners' communities and to validate results with regard to increasing transparency of artificial intelligence applications., Pruning and improvement of the vast array of performance attribution models by contributing to the development of methodologies for reducing the false discovery rate in financial research and applied financial investment management., Create an excellent network of researchers in Europe with lasting collaboration beyond the lifetime of the Action., Bringing technological, quantitative and economic researchers together, to tackle future research that can only be done in an interdisciplinary setting, and getting actively involved in the blockchain and FinTech communities across Europe, to constantly monitor developments, get input and disseminate results., Establish an inclusive community of researchers on methodological and technological themes in Machine Learning and Artificial Intelligence, to promote Early Career Investigators and increase their visibility., Disseminate the results of the Action's activities to the scientific community, European institutions and to the general public., Significantly improve the gender equality in the fields of the Action. | F24: Yes | H24: No | J24: Yes | K24: Yes | L24: No | M24: 0 | N24: WG 1 | P24: Yes
A25: 44754.633 | B25: vassilios.papavassiliou@ucd.ie | C25: Ireland | D25: A discussion paper on sovereign bond return predictability using machine learning methods | E25: Disseminate to the public and share with regulators the results on investment product performance evaluation., Disseminate the results of the Action's activities to the scientific community, European institutions and to the general public. | F25: Yes | H25: No | J25: No | K25: Yes | L25: No | M25: 0 | N25: WG 1, WG 3 | P25: No
A26: 44754.815 | B26: valerio.poti@ucd.ie | C26: Ireland | D26: Anything else useful for the COST Action, not mentioned below | E26: To develop blended approaches to evaluate innovative financial services and their providers, especially in the FinTech domain, building on Machine Learning methods, focussing on prediction (early warning) of operational fragility, fraudulent and illegal behaviour ranging from appropriation of loaned funds to money-laundering activities., Pruning and improvement of the vast array of performance attribution models by contributing to the development of methodologies for reducing the false discovery rate in financial research and applied financial investment management., Disseminate the results of the Action's activities to the scientific community, European institutions and to the general public., Significantly improve the gender equality in the fields of the Action. | F26: Yes | H26: Yes | J26: Yes | K26: Yes | L26: No | M26: 0 | N26: WG 1 | P26: Yes
A27: 44735.43 | B27: alessandra.tanda@unipv.it | C27: Italy | D27: Anything else useful for the COST Action, not mentioned below, An internal database of collected (scraped) financial time series from exchanges and regional consolidation platforms optimised for accessibility to all partners, Strategy to engage stakeholders in the Action (including revisions in month 24 and 36) | E27: Disseminate to the public and share with regulators the results on investment product performance evaluation., Create an excellent network of researchers in Europe with lasting collaboration beyond the lifetime of the Action., Transfer knowledge in terms of expertise, scientific tools and human resources across the different disciplines and between academia and industry., Maximize the job opportunities for PhD students and Early Career Investigators., Significantly improve the gender equality in the fields of the Action. | F27: No | H27: No | I27: Yes | J27: Yes | K27: Yes | L27: No | M27: 0 | N27: WG 1, WG 3
A28: 44735.451 | B28: daniele.marazzina@polimi.it | C28: Italy | D28: Anything else useful for the COST Action, not mentioned below, A database which contains pre-ICO documentation and post-ICO performance (ROI and, A database which contains data on crowdfunding/P2P platform features useful for rating platform integrity and to predict fraud | E28: Create an excellent network of researchers in Europe with lasting collaboration beyond the lifetime of the Action., Transfer knowledge in terms of expertise, scientific tools and human resources across the different disciplines and between academia and industry., Disseminate the results of the Action's activities to the scientific community, European institutions and to the general public., Significantly improve the gender equality in the fields of the Action. | F28: No | H28: Yes | I28: Yes | J28: No | K28: Yes | L28: No | M28: 0 | N28: WG 1, WG 2, WG 3
A29: 44741.569 | B29: daniele.marazzina@polimi.it | C29: Italy | D29: Anything else useful for the COST Action, not mentioned below, A database which contains pre-ICO documentation and post-ICO performance (ROI and, A database which contains data on crowdfunding/P2P platform features useful for rating platform integrity and to predict fraud | E29: Anything else useful and related to the below topics, Create an excellent network of researchers in Europe with lasting collaboration beyond the lifetime of the Action., Bridging the gap between practitioners from the finance industry, academics and regulators by setting up a common knowledge exchange platform., Maximize the job opportunities for PhD students and Early Career Investigators., Disseminate the results of the Action's activities to the scientific community, European institutions and to the general public., Significantly improve the gender equality in the fields of the Action. | F29: Yes | H29: Yes | J29: No | K29: Yes | L29: Yes | M29: 0 | N29: WG 1, WG 2, WG 3 | P29: No
A30: 44749.629 | B30: maria.iannario@unina.it | C30: Italy | D30: A discussion paper for possible approaches to building a statistically valid back-testing framework | E30: Disseminate to the public and share with regulators the results on investment product performance evaluation., Create an excellent network of researchers in Europe with lasting collaboration beyond the lifetime of the Action., Bridging the gap between practitioners from the finance industry, academics and regulators by setting up a common knowledge exchange platform., Transfer knowledge in terms of expertise, scientific tools and human resources across the different disciplines and between academia and industry., Overcome the siloing of research topics by country and achieve geographical and demographical diversity, with special attention to COST Inclusiveness Target countries., Maximize the job opportunities for PhD students and Early Career Investigators., Disseminate the results of the Action's activities to the scientific community, European institutions and to the general public., Significantly improve the gender equality in the fields of the Action. | F30: Yes | H30: Yes | J30: Yes | K30: Yes | L30: No | M30: 0 | N30: WG 2 | O30: Women in Fintech Datathon is a data mining event (data analysis) organized by the Women in Fintech Conference Committee represented by several researchers of the Cost Action FinAI CA19130, University of Tirana and University of Naples Federico II (for more details, please see the following link: https://fin-ai.eu/datathon/). It aims to promote the analysis of data on the goals of the Women in Fintech II Conference, and more general in the field of the FinAI Action. Among the main topics to be developed by means of (open access and real) data analysis: Gender diversity in Fintech corporate world, Fintech gender diversity in different EU countries, Gender pay gap in Fintech roles. It involves teams from every European country. The team should be made up of maximum 5 members (male or female), which can be enrolled in bachelor, master or PhD programmes. High-performing teams are composed of individuals with specialized expertise and complementary skills. It creates cooperation and improves qualification of next generation. | P30: Yes
A31: 44738.512 | B31: rr@lu.lv | C31: Latvia | D31: No | E31: Create an excellent network of researchers in Europe with lasting collaboration beyond the lifetime of the Action., Bringing technological, quantitative and economic researchers together, to tackle future research that can only be done in an interdisciplinary setting, and getting actively involved in the blockchain and FinTech communities across Europe, to constantly monitor developments, get input and disseminate results., Transfer knowledge in terms of expertise, scientific tools and human resources across the different disciplines and between academia and industry., Prepare competitive European researchers for a fruitful career in an international environment through intensive use of Short Term Scientific Missions (STSM) and joint educational programs with industrial partners., Disseminate the results of the Action's activities to the scientific community, European institutions and to the general public. | F31: No | H31: No | J31: Yes | K31: Yes | L31: No | M31: 0 | N31: WG 1 | P31: No
A32: 44729.577 | B32: audkaba@ktu.lt | C32: Lithuania | D32: Methodological discussion papers on AI models to generate “failed trials” of investment product producers and on quantitative strategies with the usage of the promising field of network data analysis exchanges and regional consolidation platforms optimised for accessibility to all partners | E32: Pruning and improvement of the vast array of performance attribution models by contributing to the development of methodologies for reducing the false discovery rate in financial research and applied financial investment management., Disseminate to the public and share with regulators the results on investment product performance evaluation., Disseminate the results of the Action's activities to the scientific community, European institutions and to the general public. | F32: Yes | G32: Yes | H32: No | I32: Yes | J32: Yes | K32: No | L32: Yes | M32: 0 | N32: WG 2
A33: 44735.45 | B33: kristina.sutiene@ktu.lt | C33: Lithuania | D33: Report on good examples and best practices for a transparent finance industry with guidelines to improve transparency | E33: Disseminate to the public and share with regulators the results on investment product performance evaluation., Disseminate the results of the Action's activities to the scientific community, European institutions and to the general public. | F33: Yes | G33: No | H33: No | I33: Yes | J33: Yes | K33: No | L33: No | M33: 0 | N33: WG 2 | O33: A reviewer in TINFIN conference https://sites.google.com/net.efzg.hr/tinfinconference/home/programme-committee | P33: Yes
A34: 44753.588 | B34: audkaba@ktu.lt | C34: Lithuania | D34: Methodological discussion paper on the design of stress tests for the evaluation of AI and ML models under shifting financial conditions to improve the robustness of models, Report on good examples and best practices for a transparent finance industry with guidelines to improve transparency | E34: The development of conceptual and methodological tools for establishing when blackbox models are admissible and, to the extent possible, making them more transparent and/or replacing them with interpretable and explainable models., Disseminate to the public and share with regulators the results on investment product performance evaluation., Create an excellent network of researchers in Europe with lasting collaboration beyond the lifetime of the Action., Bridging the gap between practitioners from the finance industry, academics and regulators by setting up a common knowledge exchange platform., Transfer knowledge in terms of expertise, scientific tools and human resources across the different disciplines and between academia and industry., Prepare competitive European researchers for a fruitful career in an international environment through intensive use of Short Term Scientific Missions (STSM) and joint educational programs with industrial partners., Disseminate the results of the Action's activities to the scientific community, European institutions and to the general public. | F34: Yes | H34: Yes | J34: Yes | K34: Yes | L34: Yes | M34: 0 | N34: WG 2 | O34: Network expansion performed | P34: Yes
A35: 44754.545 | B35: angele@acrosslimits.com | C35: Malta | D35: Anything else useful for the COST Action, not mentioned below | E35: Create an excellent network of researchers in Europe with lasting collaboration beyond the lifetime of the Action., Bringing technological, quantitative and economic researchers together, to tackle future research that can only be done in an interdisciplinary setting, and getting actively involved in the blockchain and FinTech communities across Europe, to constantly monitor developments, get input and disseminate results. | F35: No | H35: No | J35: No | K35: Yes | L35: Yes | M35: 0 | N35: WG 2 | O35: We are trying to form consortia for various European proposals for funding and involving other partners of the Cost Action | P35: Yes
A36: 44757.638 | B36: dbevan@stmartins.edu | C36: Malta | D36: Anything else useful for the COST Action, not mentioned below | E36: To develop blended approaches to evaluate innovative financial services and their providers, especially in the FinTech domain, building on Machine Learning methods, focussing on prediction (early warning) of operational fragility, fraudulent and illegal behaviour ranging from appropriation of loaned funds to money-laundering activities., The development of conceptual and methodological tools for establishing when blackbox models are admissible and, to the extent possible, making them more transparent and/or replacing them with interpretable and explainable models., Create an excellent network of researchers in Europe with lasting collaboration beyond the lifetime of the Action., Transfer knowledge in terms of expertise, scientific tools and human resources across the different disciplines and between academia and industry., Overcome the siloing of research topics by country and achieve geographical and demographical diversity, with special attention to COST Inclusiveness Target countries., Disseminate the results of the Action's activities to the scientific community, European institutions and to the general public. | F36: No | H36: Yes | J36: Yes | K36: Yes | L36: No | M36: 0 | N36: WG 1, WG 2, WG 3 | O36: 1. Significant contribution in 2022 through publication and conference presentations (ISBEE July 2022) to making academic / professional business-ethics community aware of prevalent current ethical attitudes (and discourses/contexts) operating in the Fintech community with particular reference to (i) the potentially dysfunctional application of 'black box' amorality and as contrasted with the complexity (ii) 'all tech is human'. 2. Acting as deputy network co-ordinator to support the continuing energy in the Action and both its longevity and interdisciplinary interactions, by improving professional and scholarly understanding and communication of AI ethics. | P36: Yes
A37: 44732.91 | B37: lameski@finki.ukim.mk | C37: N. Macedonia | D37: Discussion papers (DP) on the methodology for evaluating/rating ICOs and crowdfunding/P2P platforms and for detection/early warning about fraud/illegal behaviour with emphasis on the application of AI tools, A position paper and roadmap on mitigating risks connected with the increased use of digital assets, A discussion paper for possible approaches to building a statistically valid back-testing framework, Position papers, aimed at regulators and policy-makers, on methodology (with examples of formal criteria) for testing AI techniques in real-time, Report on good examples and best practices for a transparent finance industry with guidelines to improve transparency | E37: The development of conceptual and methodological tools for establishing when blackbox models are admissible and, to the extent possible, making them more transparent and/or replacing them with interpretable and explainable models., To receive input from regulators and practitioners' communities and to validate results with regard to increasing transparency of artificial intelligence applications., Disseminate to the public and share with regulators the results on investment product performance evaluation., Create an excellent network of researchers in Europe with lasting collaboration beyond the lifetime of the Action., Bringing technological, quantitative and economic researchers together, to tackle future research that can only be done in an interdisciplinary setting, and getting actively involved in the blockchain and FinTech communities across Europe, to constantly monitor developments, get input and disseminate results., Establish an inclusive community of researchers on methodological and technological themes in Machine Learning and Artificial Intelligence, to promote Early Career Investigators and increase their visibility., Disseminate the results of the Action's activities to the scientific community, European institutions and to the general public. | F37: No | G37: No | H37: Yes | I37: Yes | J37: Yes | K37: Yes | L37: No | M37: 0 | N37: WG 2
A38: 44748.568 | B38: r.j.kleverlaan@uu.nl | C38: Netherlands | D38: Anything else useful for the COST Action, not mentioned below, Strategy to engage stakeholders in the Action (including revisions in month 24 and 36) | E38: Create an excellent network of researchers in Europe with lasting collaboration beyond the lifetime of the Action., Bringing technological, quantitative and economic researchers together, to tackle future research that can only be done in an interdisciplinary setting, and getting actively involved in the blockchain and FinTech communities across Europe, to constantly monitor developments, get input and disseminate results., Bridging the gap between practitioners from the finance industry, academics and regulators by setting up a common knowledge exchange platform., Transfer knowledge in terms of expertise, scientific tools and human resources across the different disciplines and between academia and industry., Overcome the siloing of research topics by country and achieve geographical and demographical diversity, with special attention to COST Inclusiveness Target countries., Disseminate the results of the Action's activities to the scientific community, European institutions and to the general public. | F38: No | H38: No | J38: No | K38: Yes | L38: Yes | M38: 0 | N38: WG 1 | P38: Yes
A39: 44741.902 | B39: olivijaf@gmail.com | C39: North Macedonia | D39: Anything else useful for the COST Action, not mentioned below, Strategy to engage stakeholders in the Action (including revisions in month 24 and 36) | E39: To receive input from regulators and practitioners' communities and to validate results with regard to increasing transparency of artificial intelligence applications., Create an excellent network of researchers in Europe with lasting collaboration beyond the lifetime of the Action., Bridging the gap between practitioners from the finance industry, academics and regulators by setting up a common knowledge exchange platform., Establish an inclusive community of researchers on methodological and technological themes in Machine Learning and Artificial Intelligence, to promote Early Career Investigators and increase their visibility., Overcome the siloing of research topics by country and achieve geographical and demographical diversity, with special attention to COST Inclusiveness Target countries., Prepare competitive European researchers for a fruitful career in an international environment through intensive use of Short Term Scientific Missions (STSM) and joint educational programs with industrial partners., Maximize the job opportunities for PhD students and Early Career Investigators., Disseminate the results of the Action's activities to the scientific community, European institutions and to the general public., Significantly improve the gender equality in the fields of the Action. | F39: No | H39: No | J39: Yes | K39: Yes | L39: No | M39: 0 | N39: WG 1, WG 2, WG 3 | P39: Yes
A40: 44743.708 | B40: rita.pimentel@ntnu.no | C40: Norway | D40: Position papers, aimed at regulators and policy-makers, on methodology (with examples of formal criteria) for testing AI techniques in real-time | E40: Create an excellent network of researchers in Europe with lasting collaboration beyond the lifetime of the Action., Significantly improve the gender equality in the fields of the Action. | F40: No | H40: Yes | J40: Yes | K40: No | L40: No | M40: 0 | N40: WG 2 | P40: No
...

Sheet Pivot Table 2

Sheet All Countries
B1: Responded to GP1 GP2 report
A2: Albania | B2: =vlookup(A2,'Form responses 1'!$C$2:$C$129,1,false) -> Albania
A3: Austria | B3: =vlookup(A3,'Form responses 1'!$C$2:$C$129,1,false) -> Austria
A4: Belgium | B4: =vlookup(A4,'Form responses 1'!$C$2:$C$129,1,false) -> #N/A
A5: Bosnia and Herzegovina | B5: =vlookup(A5,'Form responses 1'!$C$2:$C$129,1,false) -> #N/A
A6: Bulgaria | B6: =vlookup(A6,'Form responses 1'!$C$2:$C$129,1,false) -> #N/A
A7: Croatia | B7: =vlookup(A7,'Form responses 1'!$C$2:$C$129,1,false) -> Croatia
A8: Cyprus | B8: =vlookup(A8,'Form responses 1'!$C$2:$C$129,1,false) -> Cyprus
A9: Czech Republic | B9: =vlookup(A9,'Form responses 1'!$C$2:$C$129,1,false) -> Czech Republic
A10: Denmark | B10: =vlookup(A10,'Form responses 1'!$C$2:$C$129,1,false) -> #N/A
A11: Estonia | B11: =vlookup(A11,'Form responses 1'!$C$2:$C$129,1,false) -> Estonia
A12: Finland | B12: =vlookup(A12,'Form responses 1'!$C$2:$C$129,1,false) -> #N/A
A13: France | B13: =vlookup(A13,'Form responses 1'!$C$2:$C$129,1,false) -> France
... A40: United Kingdom | B40: =vlookup(A40,'Form responses 1'!$C$2:$C$129,1,false) -> United Kingdom

Sheet MembersByCountry
A1: COST FinAI | B1: Last Name | D1: Email | E1: Country | F1: MC Membership Status | G1: Country | I1: responded to GP 1 and GP 2 Progress report
A2: Petraq | B2: Papajorgji | D2: petraq@gmail.com | E2: Albania (AL) | F2: not nominated | G2: =IFERROR(__xludf.DUMMYFUNCTION("split(E2,"" "")"),"Albania") -> Albania | H2: =IFERROR(__xludf.DUMMYFUNCTION("""COMPUTED_VALUE"""),"(AL)") -> (AL) | I2: =vlookup(G2,'All Countries'!$A$1:$B$40,2,false) -> Albania
A3: Altin | B3: Idrizi | D3: altin.idrizi@uniel.edu.al | E3: Albania (AL) | F3: not nominated | G3: =IFERROR(__xludf.DUMMYFUNCTION("split(E3,"" "")"),"Albania") -> Albania | H3: =IFERROR(__xludf.DUMMYFUNCTION("""COMPUTED_VALUE"""),"(AL)") -> (AL) | I3: =vlookup(G3,'All Countries'!$A$1:$B$40,2,false) -> Albania
A4: Endrit | B4: Xhina | D4: endri.xhina@fshn.edu.al | E4: Albania (AL) | F4: not nominated | G4: =IFERROR(__xludf.DUMMYFUNCTION("split(E4,"" "")"),"Albania") -> Albania | H4: =IFERROR(__xludf.DUMMYFUNCTION("""COMPUTED_VALUE"""),"(AL)") -> (AL) | I4: =vlookup(G4,'All Countries'!$A$1:$B$40,2,false) -> Albania
A5: Rezarta | B5: Shkurti (Perri) | D5: rezartaperri@feut.edu.al | E5: Albania (AL) | F5: Member | G5: =IFERROR(__xludf.DUMMYFUNCTION("split(E5,"" "")"),"Albania") -> Albania | H5: =IFERROR(__xludf.DUMMYFUNCTION("""COMPUTED_VALUE"""),"(AL)") -> (AL) | I5: =vlookup(G5,'All Countries'!$A$1:$B$40,2,false) -> Albania
A6: Ardita | B6: Todri | D6: ardita.todri@gmail.com | E6: Albania (AL) | F6: not nominated | G6: =IFERROR(__xludf.DUMMYFUNCTION("split(E6,"" "")"),"Albania") -> Albania | H6: =IFERROR(__xludf.DUMMYFUNCTION("""COMPUTED_VALUE"""),"(AL)") -> (AL) | I6: =vlookup(G6,'All Countries'!$A$1:$B$40,2,false) -> Albania
A7: Suela | B7: Maxhelaku | D7: suela.maxhelaku@fshn.edu.al | E7: Albania (AL) | F7: not nominated | G7: =IFERROR(__xludf.DUMMYFUNCTION("split(E7,"" "")"),"Albania") -> Albania | H7: =IFERROR(__xludf.DUMMYFUNCTION("""COMPUTED_VALUE"""),"(AL)") -> (AL) | I7: =vlookup(G7,'All Countries'!$A$1:$B$40,2,false) -> Albania
A8: Giovanni | B8: Lagioia | D8: giovanni.lagioia@uniba.it | E8: Albania (AL) | F8: Member | G8: =IFERROR(__xludf.DUMMYFUNCTION("split(E8,"" "")"),"Albania") -> Albania | H8: =IFERROR(__xludf.DUMMYFUNCTION("""COMPUTED_VALUE"""),"(AL)") -> (AL) | I8: =vlookup(G8,'All Countries'!$A$1:$B$40,2,false) -> Albania
A9: Elda | B9: Xhumari | D9: eldaxhumari@gmail.com | E9: Albania (AL) | F9: not nominated | G9: =IFERROR(__xludf.DUMMYFUNCTION("split(E9,"" "")"),"Albania") -> Albania | H9: =IFERROR(__xludf.DUMMYFUNCTION("""COMPUTED_VALUE"""),"(AL)") -> (AL) | I9: =vlookup(G9,'All Countries'!$A$1:$B$40,2,false) -> Albania
A10: Eliona | B10: Gremi | D10: Eliona.Gremi@uniel.edu.al | E10: Albania (AL) | F10: not nominated | G10: =IFERROR(__xludf.DUMMYFUNCTION("split(E10,"" "")"),"Albania") -> Albania | H10: =IFERROR(__xludf.DUMMYFUNCTION("""COMPUTED_VALUE"""),"(AL)") -> (AL) | I10: =vlookup(G10,'All Countries'!$A$1:$B$40,2,false) -> Albania
A11: LLESH | B11: LLESHAJ | D11: lleshlleshaj@feut.edu.al | E11: Albania (AL) | F11: not nominated | G11: =IFERROR(__xludf.DUMMYFUNCTION("split(E11,"" "")"),"Albania") -> Albania | H11: =IFERROR(__xludf.DUMMYFUNCTION("""COMPUTED_VALUE"""),"(AL)") -> (AL) | I11: =vlookup(G11,'All Countries'!$A$1:$B$40,2,false) -> Albania
A12: Valbona | B12: Ballkoci | D12: valbona.ballkoci@uniel.edu.al | E12: Albania (AL) | F12: not nominated | G12: =IFERROR(__xludf.DUMMYFUNCTION("split(E12,"" "")"),"Albania") -> Albania | H12: =IFERROR(__xludf.DUMMYFUNCTION("""COMPUTED_VALUE"""),"(AL)") -> (AL) | I12: =vlookup(G12,'All Countries'!$A$1:$B$40,2,false) -> Albania
A13: Anila | B13: Çekrezi | D13: vocianila@yahoo.com | E13: Albania (AL) | F13: not nominated | G13: =IFERROR(__xludf.DUMMYFUNCTION("split(E13,"" "")"),"Albania") -> Albania | H13: =IFERROR(__xludf.DUMMYFUNCTION("""COMPUTED_VALUE"""),"(AL)") -> (AL) | I13: =vlookup(G13,'All Countries'!$A$1:$B$40,2,false) -> Albania
A14: Chemseddine | B14: TIDJANI | D14: tidjani.chemseddine@gmail.com | E14: Algeria (DZ) | F14: not nominated | G14: =IFERROR(__xludf.DUMMYFUNCTION("split(E14,"" "")"),"Algeria") -> Algeria | H14: =IFERROR(__xludf.DUMMYFUNCTION("""COMPUTED_VALUE"""),"(DZ)") -> (DZ) | I14: =vlookup(G14,'All Countries'!$A$1:$B$40,2,false) -> #N/A
A15: Ronald | B15: Hochreiter | D15: ronald.hochreiter@wu.ac.at | E15: Austria (AT) | F15: Member | G15: =IFERROR(__xludf.DUMMYFUNCTION("split(E15,"" "")"),"Austria") -> Austria | H15: =IFERROR(__xludf.DUMMYFUNCTION("""COMPUTED_VALUE"""),"(AT)") -> (AT) | I15: =vlookup(G15,'All Countries'!$A$1:$B$40,2,false) -> Austria
A16: Christian | B16: Ochs | D16: christian.ochs@fincredible.at | E16: Austria (AT) | F16: Member | G16: =IFERROR(__xludf.DUMMYFUNCTION("split(E16,"" "")"),"Austria") -> Austria | H16: =IFERROR(__xludf.DUMMYFUNCTION("""COMPUTED_VALUE"""),"(AT)") -> (AT) | I16: =vlookup(G16,'All Countries'!$A$1:$B$40,2,false) -> Austria
A17: Christian | B17: Hafner | D17: christian.hafner@uclouvain.be | E17: Belgium (BE) | F17: Member | G17: =IFERROR(__xludf.DUMMYFUNCTION("split(E17,"" "")"),"Belgium") -> Belgium | H17: =IFERROR(__xludf.DUMMYFUNCTION("""COMPUTED_VALUE"""),"(BE)") -> (BE) | I17: =vlookup(G17,'All Countries'!$A$1:$B$40,2,false) -> #N/A
A18: Igor | B18: Todorović | D18: igor.todorovic@ef.unibl.org | E18: Bosnia and Herzegovina (BA) | F18: Member | G18: Bosnia and Herzegovina | I18: =vlookup(G18,'All Countries'!$A$1:$B$40,2,false) -> #N/A
A19: Jelena | B19: Poljašević | D19: jelena.poljasevic@ef.unibl.org | E19: Bosnia and Herzegovina (BA) | F19: Member | G19: Bosnia and Herzegovina | I19: =vlookup(G19,'All Countries'!$A$1:$B$40,2,false) -> #N/A
A20: Rossitza | B20: Goleva | D20: rgoleva@gmail.com | E20: Bulgaria (BG) | F20: not nominated | G20: =IFERROR(__xludf.DUMMYFUNCTION("split(E20,"" "")"),"Bulgaria") -> Bulgaria | H20: =IFERROR(__xludf.DUMMYFUNCTION("""COMPUTED_VALUE"""),"(BG)") -> (BG) | I20: =vlookup(G20,'All Countries'!$A$1:$B$40,2,false) -> #N/A
A21: Stoyan | B21: Mishev | D21: stoyan.mishev@iaps.institute | E21: Bulgaria (BG) | F21: Member | G21: =IFERROR(__xludf.DUMMYFUNCTION("split(E21,"" "")"),"Bulgaria") -> Bulgaria | H21: =IFERROR(__xludf.DUMMYFUNCTION("""COMPUTED_VALUE"""),"(BG)") -> (BG) | I21: =vlookup(G21,'All Countries'!$A$1:$B$40,2,false) -> #N/A
A22: Yassen | B22: Gorbounov | D22: ygorbounov@nbu.bg | E22: Bulgaria (BG) | F22: Member | G22: =IFERROR(__xludf.DUMMYFUNCTION("split(E22,"" "")"),"Bulgaria") -> Bulgaria | H22: =IFERROR(__xludf.DUMMYFUNCTION("""COMPUTED_VALUE"""),"(BG)") -> (BG) | I22: Bulgaria
A23: Hristina | B23: Kostadinova | D23: hkostadinova@gmail.com | E23: Bulgaria (BG) | F23: not nominated | G23: =IFERROR(__xludf.DUMMYFUNCTION("split(E23,"" "")"),"Bulgaria") -> Bulgaria | H23: =IFERROR(__xludf.DUMMYFUNCTION("""COMPUTED_VALUE"""),"(BG)") -> (BG)
A24: Silvija | B24: Vlah Jerić | D24: svlah@net.efzg.hr | E24: Croatia (HR) | F24: not nominated | G24: =IFERROR(__xludf.DUMMYFUNCTION("split(E24,"" "")"),"Croatia") -> Croatia | H24: =IFERROR(__xludf.DUMMYFUNCTION("""COMPUTED_VALUE"""),"(HR)") -> (HR) | I24: =vlookup(G24,'All Countries'!$A$1:$B$40,2,false) -> Croatia
A25: Nika | B25: Šimurina | D25: nsimurina@efzg.hr | E25: Croatia (HR) | F25: Member | G25: =IFERROR(__xludf.DUMMYFUNCTION("split(E25,"" "")"),"Croatia") -> Croatia | H25: =IFERROR(__xludf.DUMMYFUNCTION("""COMPUTED_VALUE"""),"(HR)") -> (HR) | I25: =vlookup(G25,'All Countries'!$A$1:$B$40,2,false) -> Croatia
A26: Martina | B26: Solenički | D26: mnakic@efzg.hr | E26: Croatia (HR) | F26: not nominated | G26: =IFERROR(__xludf.DUMMYFUNCTION("split(E26,"" "")"),"Croatia") -> Croatia | H26: =IFERROR(__xludf.DUMMYFUNCTION("""COMPUTED_VALUE"""),"(HR)") -> (HR) | I26: =vlookup(G26,'All Countries'!$A$1:$B$40,2,false) -> Croatia
A27: Ana | B27: Ivanisevic Hernaus | D27: ana.ivanisevic@efzg.hr | E27: Croatia (HR) | F27: Member | G27: =IFERROR(__xludf.DUMMYFUNCTION("split(E27,"" "")"),"Croatia") -> Croatia | H27: =IFERROR(__xludf.DUMMYFUNCTION("""COMPUTED_VALUE"""),"(HR)") -> (HR) | I27: =vlookup(G27,'All Countries'!$A$1:$B$40,2,false) -> Croatia
A28: Domagoj | B28: Sajter | D28: domagoj.sajter+cost@gmail.com | E28: Croatia (HR) | F28: not nominated | G28: =IFERROR(__xludf.DUMMYFUNCTION("split(E28,"" "")"),"Croatia") -> Croatia | H28: =IFERROR(__xludf.DUMMYFUNCTION("""COMPUTED_VALUE"""),"(HR)") -> (HR) | I28: =vlookup(G28,'All Countries'!$A$1:$B$40,2,false) -> Croatia
A29: Mile | B29: Bošnjak | D29: mile.bosnjak76@gmail.com | E29: Croatia (HR) | F29: not nominated | G29: =IFERROR(__xludf.DUMMYFUNCTION("split(E29,"" "")"),"Croatia") -> Croatia | H29: =IFERROR(__xludf.DUMMYFUNCTION("""COMPUTED_VALUE"""),"(HR)") -> (HR) | I29: =vlookup(G29,'All Countries'!$A$1:$B$40,2,false) -> Croatia
A30: Andreas | B30: Gregoriades | D30: andreas.gregoriades@cut.ac.cy | E30: Cyprus (CY) | F30: Member | G30: =IFERROR(__xludf.DUMMYFUNCTION("split(E30,"" "")"),"Cyprus") -> Cyprus | H30: =IFERROR(__xludf.DUMMYFUNCTION("""COMPUTED_VALUE"""),"(CY)") -> (CY) | I30: =vlookup(G30,'All Countries'!$A$1:$B$40,2,false) -> Cyprus
A31: Loizos | B31: Michael | D31: loizos@ouc.ac.cy | E31: Cyprus (CY) | F31: not nominated | G31: =IFERROR(__xludf.DUMMYFUNCTION("split(E31,"" "")"),"Cyprus") -> Cyprus | H31: =IFERROR(__xludf.DUMMYFUNCTION("""COMPUTED_VALUE"""),"(CY)") -> (CY) | I31: =vlookup(G31,'All Countries'!$A$1:$B$40,2,false) -> Cyprus
A32: Ifigenia | B32: Georgiou | D32: georgiou.i@unic.ac.cy | E32: Cyprus (CY) | F32: Member | G32: =IFERROR(__xludf.DUMMYFUNCTION("split(E32,"" "")"),"Cyprus") -> Cyprus | H32: =IFERROR(__xludf.DUMMYFUNCTION("""COMPUTED_VALUE"""),"(CY)") -> (CY) | I32: =vlookup(G32,'All Countries'!$A$1:$B$40,2,false) -> Cyprus
