Workbook

Sheet Expression of Interest
A499: As given in your e-COST profile | F499: Please indicate one secondary proposer per country | H499: Country | I499: Only name with clean formatting (no department or further precision). Please update your COST profile accordingly. Max 40 Characters | J499: Young Researcher | K499: Yes/No (as per your e-COST profile) | L499: Estimate the number of FTEs involved in research activities related to Sustainable Digital Transformation | M499: (If selected "Other", please precise in "Details" column) | N499: Add more details about your research field/experience if needed | O499: List of NNC: Link | Q499: List of European RTD Organizations (p.5 - Section 2): Link | R499: As per your e-COST profile | S499: As per your e-COST profile | T499: (3 to 5 short bullet points, clean formatting) CMD/CTRL+Enter to enter a line break in a cell | U499: (3 to 5 short bullet points, clean formatting) CMD/CTRL+Enter to enter a line break in a cell | V499: yes, no. if yes, shortly indicate your potential contribution | W499: yes/no. If yes, indicate who | X499: All columns mandatory | Y499: leave empty. to be filled in by the core team | Z499: leave empty. to be filled in by the core team | AA499: leave empty. to be filled in by the core team
A500: Title* | B500: Nr. | C500: First Name* | D500: Last Name* | E500: Email* | F500: Secondary Proposer | G500: Gender* | H500: Country* | I500: University or Company Name* | J500: Age below 40* | K500: Industry | L500: If Industry, how many FTEs? | M500: Research field* | N500: Details | O500: Near Neighbour Country (yes/no)* (not EU, not COST country) | P500: Are you an International Partner Country (yes/no)* (i.e. outside Europe) | Q500: Are you an European RTD Organisation (yes/no)* | R500: EU Institutions, Bodies, Offices and Agencies (EC/EU) (yes/no) | S500: International Organisation (yes/no) | T500: What benefits does the current COST action bring to your University?* | U500: What are your expectations of this new COST action?* | V500: Do you want to be part of the core team writing the application? | W500: Would you be available to help find additional researchers, government representatives and industry participants from your country and across Europe? | X500: All columns filled in? (All columns are mandatory) | Y500: Selected for portal | Z500: Invited to portal | AA500: Accepted invite | AB500: Notes

Sheet DataBase
A1: Cost Countries | B1: ITCs
A2: Albania | B2: Albania
A3: Armenia | B3: Armenia
A4: Austria | B4: Bosnia and Herzegovina
A5: Belgium | B5: Bulgaria
A6: Bosnia and Herzegovina | B6: Croatia
A7: Bulgaria | B7: Cyprus
A8: Croatia | B8: Czech Rupublic
A9: Cyprus | B9: Estonia
A10: Czech Republic | B10: Georgia
A11: Denmark | B11: Greece
A12: Estonia | B12: Hungary
... A26: The Republic of Moldova | B26: Ukraine
A27: Montenegro
A28: The Netherlands
A29: The Republic of North Macedonia
A30: Norway
A31: Poland
A32: Portugal
A33: Romania
A34: Serbia
A35: Slovenia
A36: Slovakia
A37: Spain
A38: Sweden
... A42: United Kingdom

Sheet Global Statistics
B1: # Required | C1: 6 | D1: 3 | E1: 3 | F1: 2 | G1: 3
A2: Country | B2: ITC | C2: Total number of applicants | D2: Gender balance (Percentage F) | E2: Young researchers (Percentage YR) | F2: From industry (Percent Yes) | G2: Fields per country | H2: Secondary Proposer indicated | I2: Remarks | K2: Research field | L2: Count | M2: Percentage
A3: =IFERROR(__xludf.DUMMYFUNCTION("UNIQUE(FILTER('Expression of Interest'!H3:H498, 'Expression of Interest'!H3:H498<>""""))"),"#N/A") -> #N/A | B3: =COUNTIF(DataBase!$B$2:$B$26,A3) > 0 -> FALSE | C3: =COUNTIF('Expression of Interest'!$H$2:$H$498, A3) -> 0 | D3: =COUNTIFS('Expression of Interest'!H:H, $A3, 'Expression of Interest'!G:G, "F") -> 0 | E3: =COUNTIFS('Expression of Interest'!H:H, $A3, 'Expression of Interest'!J:J, "Yes") -> 0 | F3: =COUNTIFS('Expression of Interest'!H:H, $A3, 'Expression of Interest'!K:K, "Yes") -> 0 | G3: =IFERROR(__xludf.DUMMYFUNCTION("COUNTA(UNIQUE(FILTER('Expression of Interest'!$M$2:$M$498, 'Expression of Interest'!$H$2:$H$498=$A3)))"),1.0) -> 1 | H3: =COUNTIFS('Expression of Interest'!H:H, $A3, 'Expression of Interest'!F:F, "Yes") -> 0 | K3: =IFERROR(__xludf.DUMMYFUNCTION("UNIQUE(FILTER('Expression of Interest'!M3:M498, 'Expression of Interest'!M3:M498<>""""))"),"#N/A") -> #N/A | L3: =COUNTIFS('Expression of Interest'!M:M, $K3) -> 0 | M3: =L3/$L$14 -> #DIV/0!
B4: =COUNTIF(DataBase!$B$2:$B$26,A4) > 0 -> FALSE | C4: =COUNTIF('Expression of Interest'!$H$2:$H$498, A4) -> 0 | D4: =COUNTIFS('Expression of Interest'!H:H, $A4, 'Expression of Interest'!G:G, "F") -> 0 | E4: =COUNTIFS('Expression of Interest'!H:H, $A4, 'Expression of Interest'!J:J, "Yes") -> 0 | F4: =COUNTIFS('Expression of Interest'!H:H, $A4, 'Expression of Interest'!K:K, "Yes") -> 0 | G4: =IFERROR(__xludf.DUMMYFUNCTION("COUNTA(UNIQUE(FILTER('Expression of Interest'!$M$2:$M$498, 'Expression of Interest'!$H$2:$H$498=$A4)))"),0.0) -> 0 | H4: =COUNTIFS('Expression of Interest'!H:H, $A4, 'Expression of Interest'!F:F, "Yes") -> 0 | L4: =COUNTIFS('Expression of Interest'!M:M, $K4) -> 0 | M4: =L4/$L$14 -> #DIV/0!
B5: =COUNTIF(DataBase!$B$2:$B$26,A5) > 0 -> FALSE | C5: =COUNTIF('Expression of Interest'!$H$2:$H$498, A5) -> 0 | D5: =COUNTIFS('Expression of Interest'!H:H, $A5, 'Expression of Interest'!G:G, "F") -> 0 | E5: =COUNTIFS('Expression of Interest'!H:H, $A5, 'Expression of Interest'!J:J, "Yes") -> 0 | F5: =COUNTIFS('Expression of Interest'!H:H, $A5, 'Expression of Interest'!K:K, "Yes") -> 0 | G5: =IFERROR(__xludf.DUMMYFUNCTION("COUNTA(UNIQUE(FILTER('Expression of Interest'!$M$2:$M$498, 'Expression of Interest'!$H$2:$H$498=$A5)))"),0.0) -> 0 | H5: =COUNTIFS('Expression of Interest'!H:H, $A5, 'Expression of Interest'!F:F, "Yes") -> 0 | L5: =COUNTIFS('Expression of Interest'!M:M, $K5) -> 0 | M5: =L5/$L$14 -> #DIV/0!
B6: =COUNTIF(DataBase!$B$2:$B$26,A6) > 0 -> FALSE | C6: =COUNTIF('Expression of Interest'!$H$2:$H$498, A6) -> 0 | D6: =COUNTIFS('Expression of Interest'!H:H, $A6, 'Expression of Interest'!G:G, "F") -> 0 | E6: =COUNTIFS('Expression of Interest'!H:H, $A6, 'Expression of Interest'!J:J, "Yes") -> 0 | F6: =COUNTIFS('Expression of Interest'!H:H, $A6, 'Expression of Interest'!K:K, "Yes") -> 0 | G6: =IFERROR(__xludf.DUMMYFUNCTION("COUNTA(UNIQUE(FILTER('Expression of Interest'!$M$2:$M$498, 'Expression of Interest'!$H$2:$H$498=$A6)))"),0.0) -> 0 | H6: =COUNTIFS('Expression of Interest'!H:H, $A6, 'Expression of Interest'!F:F, "Yes") -> 0 | L6: =COUNTIFS('Expression of Interest'!M:M, $K6) -> 0 | M6: =L6/$L$14 -> #DIV/0!
B7: =COUNTIF(DataBase!$B$2:$B$26,A7) > 0 -> FALSE | C7: =COUNTIF('Expression of Interest'!$H$2:$H$498, A7) -> 0 | D7: =COUNTIFS('Expression of Interest'!H:H, $A7, 'Expression of Interest'!G:G, "F") -> 0 | E7: =COUNTIFS('Expression of Interest'!H:H, $A7, 'Expression of Interest'!J:J, "Yes") -> 0 | F7: =COUNTIFS('Expression of Interest'!H:H, $A7, 'Expression of Interest'!K:K, "Yes") -> 0 | G7: =IFERROR(__xludf.DUMMYFUNCTION("COUNTA(UNIQUE(FILTER('Expression of Interest'!$M$2:$M$498, 'Expression of Interest'!$H$2:$H$498=$A7)))"),0.0) -> 0 | H7: =COUNTIFS('Expression of Interest'!H:H, $A7, 'Expression of Interest'!F:F, "Yes") -> 0 | L7: =COUNTIFS('Expression of Interest'!M:M, $K7) -> 0 | M7: =L7/$L$14 -> #DIV/0!
B8: =COUNTIF(DataBase!$B$2:$B$26,A8) > 0 -> FALSE | C8: =COUNTIF('Expression of Interest'!$H$2:$H$498, A8) -> 0 | D8: =COUNTIFS('Expression of Interest'!H:H, $A8, 'Expression of Interest'!G:G, "F") -> 0 | E8: =COUNTIFS('Expression of Interest'!H:H, $A8, 'Expression of Interest'!J:J, "Yes") -> 0 | F8: =COUNTIFS('Expression of Interest'!H:H, $A8, 'Expression of Interest'!K:K, "Yes") -> 0 | G8: =IFERROR(__xludf.DUMMYFUNCTION("COUNTA(UNIQUE(FILTER('Expression of Interest'!$M$2:$M$498, 'Expression of Interest'!$H$2:$H$498=$A8)))"),0.0) -> 0 | H8: =COUNTIFS('Expression of Interest'!H:H, $A8, 'Expression of Interest'!F:F, "Yes") -> 0 | L8: =COUNTIFS('Expression of Interest'!M:M, $K8) -> 0 | M8: =L8/$L$14 -> #DIV/0!
B9: =COUNTIF(DataBase!$B$2:$B$26,A9) > 0 -> FALSE | C9: =COUNTIF('Expression of Interest'!$H$2:$H$498, A9) -> 0 | D9: =COUNTIFS('Expression of Interest'!H:H, $A9, 'Expression of Interest'!G:G, "F") -> 0 | E9: =COUNTIFS('Expression of Interest'!H:H, $A9, 'Expression of Interest'!J:J, "Yes") -> 0 | F9: =COUNTIFS('Expression of Interest'!H:H, $A9, 'Expression of Interest'!K:K, "Yes") -> 0 | G9: =IFERROR(__xludf.DUMMYFUNCTION("COUNTA(UNIQUE(FILTER('Expression of Interest'!$M$2:$M$498, 'Expression of Interest'!$H$2:$H$498=$A9)))"),0.0) -> 0 | H9: =COUNTIFS('Expression of Interest'!H:H, $A9, 'Expression of Interest'!F:F, "Yes") -> 0 | L9: =COUNTIFS('Expression of Interest'!M:M, $K9) -> 0 | M9: =L9/$L$14 -> #DIV/0!
B10: =COUNTIF(DataBase!$B$2:$B$26,A10) > 0 -> FALSE | C10: =COUNTIF('Expression of Interest'!$H$2:$H$498, A10) -> 0 | D10: =COUNTIFS('Expression of Interest'!H:H, $A10, 'Expression of Interest'!G:G, "F") -> 0 | E10: =COUNTIFS('Expression of Interest'!H:H, $A10, 'Expression of Interest'!J:J, "Yes") -> 0 | F10: =COUNTIFS('Expression of Interest'!H:H, $A10, 'Expression of Interest'!K:K, "Yes") -> 0 | G10: =IFERROR(__xludf.DUMMYFUNCTION("COUNTA(UNIQUE(FILTER('Expression of Interest'!$M$2:$M$498, 'Expression of Interest'!$H$2:$H$498=$A10)))"),0.0) -> 0 | H10: =COUNTIFS('Expression of Interest'!H:H, $A10, 'Expression of Interest'!F:F, "Yes") -> 0 | L10: =COUNTIFS('Expression of Interest'!M:M, $K10) -> 0 | M10: =L10/$L$14 -> #DIV/0!
B11: =COUNTIF(DataBase!$B$2:$B$26,A11) > 0 -> FALSE | C11: =COUNTIF('Expression of Interest'!$H$2:$H$498, A11) -> 0 | D11: =COUNTIFS('Expression of Interest'!H:H, $A11, 'Expression of Interest'!G:G, "F") -> 0 | E11: =COUNTIFS('Expression of Interest'!H:H, $A11, 'Expression of Interest'!J:J, "Yes") -> 0 | F11: =COUNTIFS('Expression of Interest'!H:H, $A11, 'Expression of Interest'!K:K, "Yes") -> 0 | G11: =IFERROR(__xludf.DUMMYFUNCTION("COUNTA(UNIQUE(FILTER('Expression of Interest'!$M$2:$M$498, 'Expression of Interest'!$H$2:$H$498=$A11)))"),0.0) -> 0 | H11: =COUNTIFS('Expression of Interest'!H:H, $A11, 'Expression of Interest'!F:F, "Yes") -> 0 | L11: =COUNTIFS('Expression of Interest'!M:M, $K11) -> 0 | M11: =L11/$L$14 -> #DIV/0!
B12: =COUNTIF(DataBase!$B$2:$B$26,A12) > 0 -> FALSE | C12: =COUNTIF('Expression of Interest'!$H$2:$H$498, A12) -> 0 | D12: =COUNTIFS('Expression of Interest'!H:H, $A13, 'Expression of Interest'!G:G, "F") -> 0 | E12: =COUNTIFS('Expression of Interest'!H:H, $A13, 'Expression of Interest'!J:J, "Yes") -> 0 | F12: =COUNTIFS('Expression of Interest'!H:H, $A12, 'Expression of Interest'!K:K, "Yes") -> 0 | G12: =IFERROR(__xludf.DUMMYFUNCTION("COUNTA(UNIQUE(FILTER('Expression of Interest'!$M$2:$M$498, 'Expression of Interest'!$H$2:$H$498=$A13)))"),0.0) -> 0 | H12: =COUNTIFS('Expression of Interest'!H:H, $A12, 'Expression of Interest'!F:F, "Yes") -> 0 | L12: =COUNTIFS('Expression of Interest'!M:M, $K12) -> 0 | M12: =L12/$L$14 -> #DIV/0!
B13: =COUNTIF(DataBase!$B$2:$B$26,A13) > 0 -> FALSE | C13: =COUNTIF('Expression of Interest'!$H$2:$H$498, A13) -> 0 | D13: =COUNTIFS('Expression of Interest'!H:H, $A14, 'Expression of Interest'!G:G, "F") -> 0 | E13: =COUNTIFS('Expression of Interest'!H:H, $A14, 'Expression of Interest'!J:J, "Yes") -> 0 | F13: =COUNTIFS('Expression of Interest'!H:H, $A13, 'Expression of Interest'!K:K, "Yes") -> 0 | G13: =IFERROR(__xludf.DUMMYFUNCTION("COUNTA(UNIQUE(FILTER('Expression of Interest'!$M$2:$M$498, 'Expression of Interest'!$H$2:$H$498=$A14)))"),0.0) -> 0 | H13: =COUNTIFS('Expression of Interest'!H:H, $A13, 'Expression of Interest'!F:F, "Yes") -> 0 | L13: =COUNTIFS('Expression of Interest'!M:M, $K13) -> 0 | M13: =L13/$L$14 -> #DIV/0!
B14: =COUNTIF(DataBase!$B$2:$B$26,A14) > 0 -> FALSE | C14: =COUNTIF('Expression of Interest'!$H$2:$H$498, A14) -> 0 | D14: =COUNTIFS('Expression of Interest'!H:H, $A14, 'Expression of Interest'!G:G, "F") -> 0 | E14: =COUNTIFS('Expression of Interest'!H:H, $A14, 'Expression of Interest'!J:J, "Yes") -> 0 | F14: =COUNTIFS('Expression of Interest'!H:H, $A14, 'Expression of Interest'!K:K, "Yes") -> 0 | G14: =IFERROR(__xludf.DUMMYFUNCTION("COUNTA(UNIQUE(FILTER('Expression of Interest'!$M$2:$M$498, 'Expression of Interest'!$H$2:$H$498=$A14)))"),0.0) -> 0 | H14: =COUNTIFS('Expression of Interest'!H:H, $A14, 'Expression of Interest'!F:F, "Yes") -> 0 | L14: =SUM(L3:L13) -> 0
B15: =COUNTIF(DataBase!$B$2:$B$26,A15) > 0 -> FALSE | C15: =COUNTIF('Expression of Interest'!$H$2:$H$498, A15) -> 0 | D15: =COUNTIFS('Expression of Interest'!H:H, $A15, 'Expression of Interest'!G:G, "F") -> 0 | E15: =COUNTIFS('Expression of Interest'!H:H, $A15, 'Expression of Interest'!J:J, "Yes") -> 0 | F15: =COUNTIFS('Expression of Interest'!H:H, $A15, 'Expression of Interest'!K:K, "Yes") -> 0 | G15: =IFERROR(__xludf.DUMMYFUNCTION("COUNTA(UNIQUE(FILTER('Expression of Interest'!$M$2:$M$498, 'Expression of Interest'!$H$2:$H$498=$A15)))"),0.0) -> 0 | H15: =COUNTIFS('Expression of Interest'!H:H, $A15, 'Expression of Interest'!F:F, "Yes") -> 0
B16: =COUNTIF(DataBase!$B$2:$B$26,A16) > 0 -> FALSE | C16: =COUNTIF('Expression of Interest'!$H$2:$H$498, A16) -> 0 | D16: =COUNTIFS('Expression of Interest'!H:H, $A16, 'Expression of Interest'!G:G, "F") -> 0 | E16: =COUNTIFS('Expression of Interest'!H:H, $A16, 'Expression of Interest'!J:J, "Yes") -> 0 | F16: =COUNTIFS('Expression of Interest'!H:H, $A16, 'Expression of Interest'!K:K, "Yes") -> 0 | G16: =IFERROR(__xludf.DUMMYFUNCTION("COUNTA(UNIQUE(FILTER('Expression of Interest'!$M$2:$M$498, 'Expression of Interest'!$H$2:$H$498=$A16)))"),0.0) -> 0 | H16: =COUNTIFS('Expression of Interest'!H:H, $A16, 'Expression of Interest'!F:F, "Yes") -> 0
B17: =COUNTIF(DataBase!$B$2:$B$26,A17) > 0 -> FALSE | C17: =COUNTIF('Expression of Interest'!$H$2:$H$498, A17) -> 0 | D17: =COUNTIFS('Expression of Interest'!H:H, $A17, 'Expression of Interest'!G:G, "F") -> 0 | E17: =COUNTIFS('Expression of Interest'!H:H, $A17, 'Expression of Interest'!J:J, "Yes") -> 0 | F17: =COUNTIFS('Expression of Interest'!H:H, $A17, 'Expression of Interest'!K:K, "Yes") -> 0 | G17: =IFERROR(__xludf.DUMMYFUNCTION("COUNTA(UNIQUE(FILTER('Expression of Interest'!$M$2:$M$498, 'Expression of Interest'!$H$2:$H$498=$A17)))"),0.0) -> 0 | H17: =COUNTIFS('Expression of Interest'!H:H, $A17, 'Expression of Interest'!F:F, "Yes") -> 0
B18: =COUNTIF(DataBase!$B$2:$B$26,A18) > 0 -> FALSE | C18: =COUNTIF('Expression of Interest'!$H$2:$H$498, A18) -> 0 | D18: =COUNTIFS('Expression of Interest'!H:H, $A18, 'Expression of Interest'!G:G, "F") -> 0 | E18: =COUNTIFS('Expression of Interest'!H:H, $A18, 'Expression of Interest'!J:J, "Yes") -> 0 | F18: =COUNTIFS('Expression of Interest'!H:H, $A18, 'Expression of Interest'!K:K, "Yes") -> 0 | G18: =IFERROR(__xludf.DUMMYFUNCTION("COUNTA(UNIQUE(FILTER('Expression of Interest'!$M$2:$M$498, 'Expression of Interest'!$H$2:$H$498=$A18)))"),0.0) -> 0 | H18: =COUNTIFS('Expression of Interest'!H:H, $A18, 'Expression of Interest'!F:F, "Yes") -> 0 | K18: COST countries without applicants
B19: =COUNTIF(DataBase!$B$2:$B$26,A19) > 0 -> FALSE | C19: =COUNTIF('Expression of Interest'!$H$2:$H$498, A19) -> 0 | D19: =COUNTIFS('Expression of Interest'!H:H, $A19, 'Expression of Interest'!G:G, "F") -> 0 | E19: =COUNTIFS('Expression of Interest'!H:H, $A19, 'Expression of Interest'!J:J, "Yes") -> 0 | F19: =COUNTIFS('Expression of Interest'!H:H, $A19, 'Expression of Interest'!K:K, "Yes") -> 0 | G19: =IFERROR(__xludf.DUMMYFUNCTION("COUNTA(UNIQUE(FILTER('Expression of Interest'!$M$2:$M$498, 'Expression of Interest'!$H$2:$H$498=$A19)))"),0.0) -> 0 | H19: =COUNTIFS('Expression of Interest'!H:H, $A19, 'Expression of Interest'!F:F, "Yes") -> 0 | K19: =IFERROR(__xludf.DUMMYFUNCTION("FILTER(DataBase!A2:A42, ISNA(MATCH(DataBase!A2:A42, A3:A48, 0))) "),"Albania") -> Albania
B20: =COUNTIF(DataBase!$B$2:$B$26,A20) > 0 -> FALSE | C20: =COUNTIF('Expression of Interest'!$H$2:$H$498, A20) -> 0 | D20: =COUNTIFS('Expression of Interest'!H:H, $A20, 'Expression of Interest'!G:G, "F") -> 0 | E20: =COUNTIFS('Expression of Interest'!H:H, $A20, 'Expression of Interest'!J:J, "Yes") -> 0 | F20: =COUNTIFS('Expression of Interest'!H:H, $A20, 'Expression of Interest'!K:K, "Yes") -> 0 | G20: =IFERROR(__xludf.DUMMYFUNCTION("COUNTA(UNIQUE(FILTER('Expression of Interest'!$M$2:$M$498, 'Expression of Interest'!$H$2:$H$498=$A20)))"),0.0) -> 0 | H20: =COUNTIFS('Expression of Interest'!H:H, $A20, 'Expression of Interest'!F:F, "Yes") -> 0 | K20: =IFERROR(__xludf.DUMMYFUNCTION("""COMPUTED_VALUE"""),"Armenia") -> Armenia
B21: =COUNTIF(DataBase!$B$2:$B$26,A21) > 0 -> FALSE | C21: =COUNTIF('Expression of Interest'!$H$2:$H$498, A21) -> 0 | D21: =COUNTIFS('Expression of Interest'!H:H, $A21, 'Expression of Interest'!G:G, "F") -> 0 | E21: =COUNTIFS('Expression of Interest'!H:H, $A21, 'Expression of Interest'!J:J, "Yes") -> 0 | F21: =COUNTIFS('Expression of Interest'!H:H, $A21, 'Expression of Interest'!K:K, "Yes") -> 0 | G21: =IFERROR(__xludf.DUMMYFUNCTION("COUNTA(UNIQUE(FILTER('Expression of Interest'!$M$2:$M$498, 'Expression of Interest'!$H$2:$H$498=$A21)))"),0.0) -> 0 | H21: =COUNTIFS('Expression of Interest'!H:H, $A21, 'Expression of Interest'!F:F, "Yes") -> 0 | K21: =IFERROR(__xludf.DUMMYFUNCTION("""COMPUTED_VALUE"""),"Austria") -> Austria
B22: =COUNTIF(DataBase!$B$2:$B$26,A22) > 0 -> FALSE | C22: =COUNTIF('Expression of Interest'!$H$2:$H$498, A22) -> 0 | D22: =COUNTIFS('Expression of Interest'!H:H, $A22, 'Expression of Interest'!G:G, "F") -> 0 | E22: =COUNTIFS('Expression of Interest'!H:H, $A22, 'Expression of Interest'!J:J, "Yes") -> 0 | F22: =COUNTIFS('Expression of Interest'!H:H, $A22, 'Expression of Interest'!K:K, "Yes") -> 0 | G22: =IFERROR(__xludf.DUMMYFUNCTION("COUNTA(UNIQUE(FILTER('Expression of Interest'!$M$2:$M$498, 'Expression of Interest'!$H$2:$H$498=$A22)))"),0.0) -> 0 | H22: =COUNTIFS('Expression of Interest'!H:H, $A22, 'Expression of Interest'!F:F, "Yes") -> 0 | K22: =IFERROR(__xludf.DUMMYFUNCTION("""COMPUTED_VALUE"""),"Belgium") -> Belgium
B23: =COUNTIF(DataBase!$B$2:$B$26,A23) > 0 -> FALSE | C23: =COUNTIF('Expression of Interest'!$H$2:$H$498, A23) -> 0 | D23: =COUNTIFS('Expression of Interest'!H:H, $A23, 'Expression of Interest'!G:G, "F") -> 0 | E23: =COUNTIFS('Expression of Interest'!H:H, $A23, 'Expression of Interest'!J:J, "Yes") -> 0 | F23: =COUNTIFS('Expression of Interest'!H:H, $A23, 'Expression of Interest'!K:K, "Yes") -> 0 | G23: =IFERROR(__xludf.DUMMYFUNCTION("COUNTA(UNIQUE(FILTER('Expression of Interest'!$M$2:$M$498, 'Expression of Interest'!$H$2:$H$498=$A23)))"),0.0) -> 0 | H23: =COUNTIFS('Expression of Interest'!H:H, $A23, 'Expression of Interest'!F:F, "Yes") -> 0 | K23: =IFERROR(__xludf.DUMMYFUNCTION("""COMPUTED_VALUE"""),"Bosnia and Herzegovina") -> Bosnia and Herzegovina
B24: =COUNTIF(DataBase!$B$2:$B$26,A24) > 0 -> FALSE | C24: =COUNTIF('Expression of Interest'!$H$2:$H$498, A24) -> 0 | D24: =COUNTIFS('Expression of Interest'!H:H, $A24, 'Expression of Interest'!G:G, "F") -> 0 | E24: =COUNTIFS('Expression of Interest'!H:H, $A24, 'Expression of Interest'!J:J, "Yes") -> 0 | F24: =COUNTIFS('Expression of Interest'!H:H, $A24, 'Expression of Interest'!K:K, "Yes") -> 0 | G24: =IFERROR(__xludf.DUMMYFUNCTION("COUNTA(UNIQUE(FILTER('Expression of Interest'!$M$2:$M$498, 'Expression of Interest'!$H$2:$H$498=$A24)))"),0.0) -> 0 | H24: =COUNTIFS('Expression of Interest'!H:H, $A24, 'Expression of Interest'!F:F, "Yes") -> 0 | K24: =IFERROR(__xludf.DUMMYFUNCTION("""COMPUTED_VALUE"""),"Bulgaria") -> Bulgaria
B25: =COUNTIF(DataBase!$B$2:$B$26,A25) > 0 -> FALSE | C25: =COUNTIF('Expression of Interest'!$H$2:$H$498, A25) -> 0 | D25: =COUNTIFS('Expression of Interest'!H:H, $A25, 'Expression of Interest'!G:G, "F") -> 0 | E25: =COUNTIFS('Expression of Interest'!H:H, $A25, 'Expression of Interest'!J:J, "Yes") -> 0 | F25: =COUNTIFS('Expression of Interest'!H:H, $A25, 'Expression of Interest'!K:K, "Yes") -> 0 | G25: =IFERROR(__xludf.DUMMYFUNCTION("COUNTA(UNIQUE(FILTER('Expression of Interest'!$M$2:$M$498, 'Expression of Interest'!$H$2:$H$498=$A25)))"),0.0) -> 0 | H25: =COUNTIFS('Expression of Interest'!H:H, $A25, 'Expression of Interest'!F:F, "Yes") -> 0 | K25: =IFERROR(__xludf.DUMMYFUNCTION("""COMPUTED_VALUE"""),"Croatia") -> Croatia
B26: =COUNTIF(DataBase!$B$2:$B$26,A26) > 0 -> FALSE | C26: =COUNTIF('Expression of Interest'!$H$2:$H$498, A26) -> 0 | D26: =COUNTIFS('Expression of Interest'!H:H, $A26, 'Expression of Interest'!G:G, "F") -> 0 | E26: =COUNTIFS('Expression of Interest'!H:H, $A26, 'Expression of Interest'!J:J, "Yes") -> 0 | F26: =COUNTIFS('Expression of Interest'!H:H, $A26, 'Expression of Interest'!K:K, "Yes") -> 0 | G26: =IFERROR(__xludf.DUMMYFUNCTION("COUNTA(UNIQUE(FILTER('Expression of Interest'!$M$2:$M$498, 'Expression of Interest'!$H$2:$H$498=$A26)))"),0.0) -> 0 | H26: =COUNTIFS('Expression of Interest'!H:H, $A26, 'Expression of Interest'!F:F, "Yes") -> 0 | K26: =IFERROR(__xludf.DUMMYFUNCTION("""COMPUTED_VALUE"""),"Cyprus") -> Cyprus
B27: =COUNTIF(DataBase!$B$2:$B$26,A27) > 0 -> FALSE | C27: =COUNTIF('Expression of Interest'!$H$2:$H$498, A27) -> 0 | D27: =COUNTIFS('Expression of Interest'!H:H, $A27, 'Expression of Interest'!G:G, "F") -> 0 | E27: =COUNTIFS('Expression of Interest'!H:H, $A27, 'Expression of Interest'!J:J, "Yes") -> 0 | F27: =COUNTIFS('Expression of Interest'!H:H, $A27, 'Expression of Interest'!K:K, "Yes") -> 0 | G27: =IFERROR(__xludf.DUMMYFUNCTION("COUNTA(UNIQUE(FILTER('Expression of Interest'!$M$2:$M$498, 'Expression of Interest'!$H$2:$H$498=$A27)))"),0.0) -> 0 | H27: =COUNTIFS('Expression of Interest'!H:H, $A27, 'Expression of Interest'!F:F, "Yes") -> 0 | K27: =IFERROR(__xludf.DUMMYFUNCTION("""COMPUTED_VALUE"""),"Czech Republic") -> Czech Republic
B28: =COUNTIF(DataBase!$B$2:$B$26,A28) > 0 -> FALSE | C28: =COUNTIF('Expression of Interest'!$H$2:$H$498, A28) -> 0 | D28: =COUNTIFS('Expression of Interest'!H:H, $A28, 'Expression of Interest'!G:G, "F") -> 0 | E28: =COUNTIFS('Expression of Interest'!H:H, $A28, 'Expression of Interest'!J:J, "Yes") -> 0 | F28: =COUNTIFS('Expression of Interest'!H:H, $A28, 'Expression of Interest'!K:K, "Yes") -> 0 | G28: =IFERROR(__xludf.DUMMYFUNCTION("COUNTA(UNIQUE(FILTER('Expression of Interest'!$M$2:$M$498, 'Expression of Interest'!$H$2:$H$498=$A28)))"),0.0) -> 0 | H28: =COUNTIFS('Expression of Interest'!H:H, $A28, 'Expression of Interest'!F:F, "Yes") -> 0 | K28: =IFERROR(__xludf.DUMMYFUNCTION("""COMPUTED_VALUE"""),"Denmark") -> Denmark
B29: =COUNTIF(DataBase!$B$2:$B$26,A29) > 0 -> FALSE | C29: =COUNTIF('Expression of Interest'!$H$2:$H$498, A29) -> 0 | D29: =COUNTIFS('Expression of Interest'!H:H, $A29, 'Expression of Interest'!G:G, "F") -> 0 | E29: =COUNTIFS('Expression of Interest'!H:H, $A29, 'Expression of Interest'!J:J, "Yes") -> 0 | F29: =COUNTIFS('Expression of Interest'!H:H, $A29, 'Expression of Interest'!K:K, "Yes") -> 0 | G29: =IFERROR(__xludf.DUMMYFUNCTION("COUNTA(UNIQUE(FILTER('Expression of Interest'!$M$2:$M$498, 'Expression of Interest'!$H$2:$H$498=$A29)))"),0.0) -> 0 | H29: =COUNTIFS('Expression of Interest'!H:H, $A29, 'Expression of Interest'!F:F, "Yes") -> 0 | K29: =IFERROR(__xludf.DUMMYFUNCTION("""COMPUTED_VALUE"""),"Estonia") -> Estonia
B30: =COUNTIF(DataBase!$B$2:$B$26,A30) > 0 -> FALSE | C30: =COUNTIF('Expression of Interest'!$H$2:$H$498, A30) -> 0 | D30: =COUNTIFS('Expression of Interest'!H:H, $A30, 'Expression of Interest'!G:G, "F") -> 0 | E30: =COUNTIFS('Expression of Interest'!H:H, $A30, 'Expression of Interest'!J:J, "Yes") -> 0 | F30: =COUNTIFS('Expression of Interest'!H:H, $A30, 'Expression of Interest'!K:K, "Yes") -> 0 | G30: =IFERROR(__xludf.DUMMYFUNCTION("COUNTA(UNIQUE(FILTER('Expression of Interest'!$M$2:$M$498, 'Expression of Interest'!$H$2:$H$498=$A30)))"),0.0) -> 0 | H30: =COUNTIFS('Expression of Interest'!H:H, $A30, 'Expression of Interest'!F:F, "Yes") -> 0 | K30: =IFERROR(__xludf.DUMMYFUNCTION("""COMPUTED_VALUE"""),"Finland") -> Finland
B31: =COUNTIF(DataBase!$B$2:$B$26,A31) > 0 -> FALSE | C31: =COUNTIF('Expression of Interest'!$H$2:$H$498, A31) -> 0 | D31: =COUNTIFS('Expression of Interest'!H:H, $A31, 'Expression of Interest'!G:G, "F") -> 0 | E31: =COUNTIFS('Expression of Interest'!H:H, $A31, 'Expression of Interest'!J:J, "Yes") -> 0 | F31: =COUNTIFS('Expression of Interest'!H:H, $A31, 'Expression of Interest'!K:K, "Yes") -> 0 | G31: =IFERROR(__xludf.DUMMYFUNCTION("COUNTA(UNIQUE(FILTER('Expression of Interest'!$M$2:$M$498, 'Expression of Interest'!$H$2:$H$498=$A31)))"),0.0) -> 0 | H31: =COUNTIFS('Expression of Interest'!H:H, $A31, 'Expression of Interest'!F:F, "Yes") -> 0 | K31: =IFERROR(__xludf.DUMMYFUNCTION("""COMPUTED_VALUE"""),"France") -> France
B32: =COUNTIF(DataBase!$B$2:$B$26,A32) > 0 -> FALSE | C32: =COUNTIF('Expression of Interest'!$H$2:$H$498, A32) -> 0 | D32: =COUNTIFS('Expression of Interest'!H:H, $A32, 'Expression of Interest'!G:G, "F") -> 0 | E32: =COUNTIFS('Expression of Interest'!H:H, $A32, 'Expression of Interest'!J:J, "Yes") -> 0 | F32: =COUNTIFS('Expression of Interest'!H:H, $A32, 'Expression of Interest'!K:K, "Yes") -> 0 | G32: =IFERROR(__xludf.DUMMYFUNCTION("COUNTA(UNIQUE(FILTER('Expression of Interest'!$M$2:$M$498, 'Expression of Interest'!$H$2:$H$498=$A32)))"),0.0) -> 0 | H32: =COUNTIFS('Expression of Interest'!H:H, $A32, 'Expression of Interest'!F:F, "Yes") -> 0 | K32: =IFERROR(__xludf.DUMMYFUNCTION("""COMPUTED_VALUE"""),"Georgia") -> Georgia
B33: =COUNTIF(DataBase!$B$2:$B$26,A33) > 0 -> FALSE | C33: =COUNTIF('Expression of Interest'!$H$2:$H$498, A33) -> 0 | D33: =COUNTIFS('Expression of Interest'!H:H, $A33, 'Expression of Interest'!G:G, "F") -> 0 | E33: =COUNTIFS('Expression of Interest'!H:H, $A33, 'Expression of Interest'!J:J, "Yes") -> 0 | F33: =COUNTIFS('Expression of Interest'!H:H, $A33, 'Expression of Interest'!K:K, "Yes") -> 0 | G33: =IFERROR(__xludf.DUMMYFUNCTION("COUNTA(UNIQUE(FILTER('Expression of Interest'!$M$2:$M$498, 'Expression of Interest'!$H$2:$H$498=$A33)))"),0.0) -> 0 | H33: =COUNTIFS('Expression of Interest'!H:H, $A33, 'Expression of Interest'!F:F, "Yes") -> 0 | K33: =IFERROR(__xludf.DUMMYFUNCTION("""COMPUTED_VALUE"""),"Germany") -> Germany
B34: =COUNTIF(DataBase!$B$2:$B$26,A34) > 0 -> FALSE | C34: =COUNTIF('Expression of Interest'!$H$2:$H$498, A34) -> 0 | D34: =COUNTIFS('Expression of Interest'!H:H, $A34, 'Expression of Interest'!G:G, "F") -> 0 | E34: =COUNTIFS('Expression of Interest'!H:H, $A34, 'Expression of Interest'!J:J, "Yes") -> 0 | F34: =COUNTIFS('Expression of Interest'!H:H, $A34, 'Expression of Interest'!K:K, "Yes") -> 0 | G34: =IFERROR(__xludf.DUMMYFUNCTION("COUNTA(UNIQUE(FILTER('Expression of Interest'!$M$2:$M$498, 'Expression of Interest'!$H$2:$H$498=$A34)))"),0.0) -> 0 | H34: =COUNTIFS('Expression of Interest'!H:H, $A34, 'Expression of Interest'!F:F, "Yes") -> 0 | K34: =IFERROR(__xludf.DUMMYFUNCTION("""COMPUTED_VALUE"""),"Greece") -> Greece
B35: =COUNTIF(DataBase!$B$2:$B$26,A35) > 0 -> FALSE | C35: =COUNTIF('Expression of Interest'!$H$2:$H$498, A35) -> 0 | D35: =COUNTIFS('Expression of Interest'!H:H, $A35, 'Expression of Interest'!G:G, "F") -> 0 | E35: =COUNTIFS('Expression of Interest'!H:H, $A35, 'Expression of Interest'!J:J, "Yes") -> 0 | F35: =COUNTIFS('Expression of Interest'!H:H, $A35, 'Expression of Interest'!K:K, "Yes") -> 0 | G35: =IFERROR(__xludf.DUMMYFUNCTION("COUNTA(UNIQUE(FILTER('Expression of Interest'!$M$2:$M$498, 'Expression of Interest'!$H$2:$H$498=$A35)))"),0.0) -> 0 | H35: =COUNTIFS('Expression of Interest'!H:H, $A35, 'Expression of Interest'!F:F, "Yes") -> 0 | K35: =IFERROR(__xludf.DUMMYFUNCTION("""COMPUTED_VALUE"""),"Hungary") -> Hungary
B36: =COUNTIF(DataBase!$B$2:$B$26,A36) > 0 -> FALSE | C36: =COUNTIF('Expression of Interest'!$H$2:$H$498, A36) -> 0 | D36: =COUNTIFS('Expression of Interest'!H:H, $A36, 'Expression of Interest'!G:G, "F") -> 0 | E36: =COUNTIFS('Expression of Interest'!H:H, $A36, 'Expression of Interest'!J:J, "Yes") -> 0 | F36: =COUNTIFS('Expression of Interest'!H:H, $A36, 'Expression of Interest'!K:K, "Yes") -> 0 | G36: =IFERROR(__xludf.DUMMYFUNCTION("COUNTA(UNIQUE(FILTER('Expression of Interest'!$M$2:$M$498, 'Expression of Interest'!$H$2:$H$498=$A36)))"),0.0) -> 0 | H36: =COUNTIFS('Expression of Interest'!H:H, $A36, 'Expression of Interest'!F:F, "Yes") -> 0 | K36: =IFERROR(__xludf.DUMMYFUNCTION("""COMPUTED_VALUE"""),"Iceland") -> Iceland
B37: =COUNTIF(DataBase!$B$2:$B$26,A37) > 0 -> FALSE | C37: =COUNTIF('Expression of Interest'!$H$2:$H$498, A37) -> 0 | D37: =COUNTIFS('Expression of Interest'!H:H, $A37, 'Expression of Interest'!G:G, "F") -> 0 | E37: =COUNTIFS('Expression of Interest'!H:H, $A37, 'Expression of Interest'!J:J, "Yes") -> 0 | F37: =COUNTIFS('Expression of Interest'!H:H, $A37, 'Expression of Interest'!K:K, "Yes") -> 0 | G37: =IFERROR(__xludf.DUMMYFUNCTION("COUNTA(UNIQUE(FILTER('Expression of Interest'!$M$2:$M$498, 'Expression of Interest'!$H$2:$H$498=$A37)))"),0.0) -> 0 | H37: =COUNTIFS('Expression of Interest'!H:H, $A37, 'Expression of Interest'!F:F, "Yes") -> 0 | K37: =IFERROR(__xludf.DUMMYFUNCTION("""COMPUTED_VALUE"""),"Ireland") -> Ireland
B38: =COUNTIF(DataBase!$B$2:$B$26,A38) > 0 -> FALSE | C38: =COUNTIF('Expression of Interest'!$H$2:$H$498, A38) -> 0 | D38: =COUNTIFS('Expression of Interest'!H:H, $A38, 'Expression of Interest'!G:G, "F") -> 0 | E38: =COUNTIFS('Expression of Interest'!H:H, $A38, 'Expression of Interest'!J:J, "Yes") -> 0 | F38: =COUNTIFS('Expression of Interest'!H:H, $A38, 'Expression of Interest'!K:K, "Yes") -> 0 | G38: =IFERROR(__xludf.DUMMYFUNCTION("COUNTA(UNIQUE(FILTER('Expression of Interest'!$M$2:$M$498, 'Expression of Interest'!$H$2:$H$498=$A38)))"),0.0) -> 0 | H38: =COUNTIFS('Expression of Interest'!H:H, $A38, 'Expression of Interest'!F:F, "Yes") -> 0 | K38: =IFERROR(__xludf.DUMMYFUNCTION("""COMPUTED_VALUE"""),"Italy") -> Italy
B39: =COUNTIF(DataBase!$B$2:$B$26,A39) > 0 -> FALSE | C39: =COUNTIF('Expression of Interest'!$H$2:$H$498, A39) -> 0 | D39: =COUNTIFS('Expression of Interest'!H:H, $A39, 'Expression of Interest'!G:G, "F") -> 0 | E39: =COUNTIFS('Expression of Interest'!H:H, $A39, 'Expression of Interest'!J:J, "Yes") -> 0 | F39: =COUNTIFS('Expression of Interest'!H:H, $A39, 'Expression of Interest'!K:K, "Yes") -> 0 | G39: =IFERROR(__xludf.DUMMYFUNCTION("COUNTA(UNIQUE(FILTER('Expression of Interest'!$M$2:$M$498, 'Expression of Interest'!$H$2:$H$498=$A39)))"),0.0) -> 0 | H39: =COUNTIFS('Expression of Interest'!H:H, $A39, 'Expression of Interest'!F:F, "Yes") -> 0 | K39: =IFERROR(__xludf.DUMMYFUNCTION("""COMPUTED_VALUE"""),"Latvia") -> Latvia
B40: =COUNTIF(DataBase!$B$2:$B$26,A40) > 0 -> FALSE | C40: =COUNTIF('Expression of Interest'!$H$2:$H$498, A40) -> 0 | D40: =COUNTIFS('Expression of Interest'!H:H, $A40, 'Expression of Interest'!G:G, "F") -> 0 | E40: =COUNTIFS('Expression of Interest'!H:H, $A40, 'Expression of Interest'!J:J, "Yes") -> 0 | F40: =COUNTIFS('Expression of Interest'!H:H, $A40, 'Expression of Interest'!K:K, "Yes") -> 0 | G40: =IFERROR(__xludf.DUMMYFUNCTION("COUNTA(UNIQUE(FILTER('Expression of Interest'!$M$2:$M$498, 'Expression of Interest'!$H$2:$H$498=$A40)))"),0.0) -> 0 | H40: =COUNTIFS('Expression of Interest'!H:H, $A40, 'Expression of Interest'!F:F, "Yes") -> 0 | K40: =IFERROR(__xludf.DUMMYFUNCTION("""COMPUTED_VALUE"""),"Lithuania") -> Lithuania
...

Sheet Accepted Statistics
B1: # Required | C1: 6 | D1: 3 | E1: 3 | F1: 2 | G1: 3
A2: Country | B2: ITC | C2: Total number of applicants | D2: Gender balance (Percentage F) | E2: Young researchers (Percentage YR) | F2: From industry (Percent Yes) | G2: Fields per country | H2: Secondary Proposer indicated | I2: Date for next action | J2: Remarks | M2: Research field | N2: Count | O2: Percentage
A3: Ireland | B3: =COUNTIF(DataBase!$B$2:$B$26,A3) > 0 -> FALSE | C3: =COUNTIFS('Expression of Interest'!H:H, A3, 'Expression of Interest'!AA:AA, "Yes") -> 0 | D3: =COUNTIFS('Expression of Interest'!H:H, $A3, 'Expression of Interest'!G:G, "F", 'Expression of Interest'!AA:AA, "Yes") -> 0 | E3: =COUNTIFS('Expression of Interest'!H:H, $A3, 'Expression of Interest'!J:J, "Yes", 'Expression of Interest'!AA:AA, "Yes") -> 0 | F3: =COUNTIFS('Expression of Interest'!H:H, $A3, 'Expression of Interest'!K:K, "Yes", 'Expression of Interest'!AA:AA, "Yes") -> 0 | G3: =IFERROR(__xludf.DUMMYFUNCTION("COUNTA(UNIQUE(FILTER('Expression of Interest'!M:M, 'Expression of Interest'!H:H=$A3, 'Expression of Interest'!AA:AA=""Yes"")))"),1.0) -> 1 | H3: =COUNTIFS('Expression of Interest'!H:H, $A3, 'Expression of Interest'!F:F, "Yes") -> 0 | J3: Only 1 uni | K3: Completed | M3: =IFERROR(__xludf.DUMMYFUNCTION("UNIQUE(FILTER('Expression of Interest'!M3:M498, 'Expression of Interest'!M3:M498<>""""))"),"#N/A") -> #N/A | N3: =COUNTIFS('Expression of Interest'!M:M, $M3) -> 0 | O3: =N3/$N$14 -> #DIV/0!
A4: Latvia | B4: =COUNTIF(DataBase!$B$2:$B$26,A4) > 0 -> TRUE | C4: =COUNTIFS('Expression of Interest'!H:H, A4, 'Expression of Interest'!AA:AA, "Yes") -> 0 | D4: =COUNTIFS('Expression of Interest'!H:H, $A4, 'Expression of Interest'!G:G, "F", 'Expression of Interest'!AA:AA, "Yes") -> 0 | E4: =COUNTIFS('Expression of Interest'!H:H, $A4, 'Expression of Interest'!J:J, "Yes", 'Expression of Interest'!AA:AA, "Yes") -> 0 | F4: =COUNTIFS('Expression of Interest'!H:H, $A4, 'Expression of Interest'!K:K, "Yes", 'Expression of Interest'!AA:AA, "Yes") -> 0 | G4: =IFERROR(__xludf.DUMMYFUNCTION("COUNTA(UNIQUE(FILTER('Expression of Interest'!M:M, 'Expression of Interest'!H:H=$A4, 'Expression of Interest'!AA:AA=""Yes"")))"),1.0) -> 1 | H4: =COUNTIFS('Expression of Interest'!H:H, $A4, 'Expression of Interest'!F:F, "Yes") -> 0 | J4: 4 from industry | K4: Action needed | N4: =COUNTIFS('Expression of Interest'!M:M, $M4) -> 0 | O4: =N4/$N$14 -> #DIV/0!
A5: Portugal | B5: =COUNTIF(DataBase!$B$2:$B$26,A5) > 0 -> TRUE | C5: =COUNTIFS('Expression of Interest'!H:H, A5, 'Expression of Interest'!AA:AA, "Yes") -> 0 | D5: =COUNTIFS('Expression of Interest'!H:H, $A5, 'Expression of Interest'!G:G, "F", 'Expression of Interest'!AA:AA, "Yes") -> 0 | E5: =COUNTIFS('Expression of Interest'!H:H, $A5, 'Expression of Interest'!J:J, "Yes", 'Expression of Interest'!AA:AA, "Yes") -> 0 | F5: =COUNTIFS('Expression of Interest'!H:H, $A5, 'Expression of Interest'!K:K, "Yes", 'Expression of Interest'!AA:AA, "Yes") -> 0 | G5: =IFERROR(__xludf.DUMMYFUNCTION("COUNTA(UNIQUE(FILTER('Expression of Interest'!M:M, 'Expression of Interest'!H:H=$A5, 'Expression of Interest'!AA:AA=""Yes"")))"),1.0) -> 1 | H5: =COUNTIFS('Expression of Interest'!H:H, $A5, 'Expression of Interest'!F:F, "Yes") -> 0 | K5: No action currently needed | N5: =COUNTIFS('Expression of Interest'!M:M, $M5) -> 0 | O5: =N5/$N$14 -> #DIV/0!
A6: Türkiye | B6: =COUNTIF(DataBase!$B$2:$B$26,A6) > 0 -> TRUE | C6: =COUNTIFS('Expression of Interest'!H:H, A6, 'Expression of Interest'!AA:AA, "Yes") -> 0 | D6: =COUNTIFS('Expression of Interest'!H:H, $A6, 'Expression of Interest'!G:G, "F", 'Expression of Interest'!AA:AA, "Yes") -> 0 | E6: =COUNTIFS('Expression of Interest'!H:H, $A6, 'Expression of Interest'!J:J, "Yes", 'Expression of Interest'!AA:AA, "Yes") -> 0 | F6: =COUNTIFS('Expression of Interest'!H:H, $A6, 'Expression of Interest'!K:K, "Yes", 'Expression of Interest'!AA:AA, "Yes") -> 0 | G6: =IFERROR(__xludf.DUMMYFUNCTION("COUNTA(UNIQUE(FILTER('Expression of Interest'!M:M, 'Expression of Interest'!H:H=$A6, 'Expression of Interest'!AA:AA=""Yes"")))"),1.0) -> 1 | H6: =COUNTIFS('Expression of Interest'!H:H, $A6, 'Expression of Interest'!F:F, "Yes") -> 0 | N6: =COUNTIFS('Expression of Interest'!M:M, $M6) -> 0 | O6: =N6/$N$14 -> #DIV/0!
A7: Slovakia | B7: =COUNTIF(DataBase!$B$2:$B$26,A7) > 0 -> TRUE | C7: =COUNTIFS('Expression of Interest'!H:H, A7, 'Expression of Interest'!AA:AA, "Yes") -> 0 | D7: =COUNTIFS('Expression of Interest'!H:H, $A7, 'Expression of Interest'!G:G, "F", 'Expression of Interest'!AA:AA, "Yes") -> 0 | E7: =COUNTIFS('Expression of Interest'!H:H, $A7, 'Expression of Interest'!J:J, "Yes", 'Expression of Interest'!AA:AA, "Yes") -> 0 | F7: =COUNTIFS('Expression of Interest'!H:H, $A7, 'Expression of Interest'!K:K, "Yes", 'Expression of Interest'!AA:AA, "Yes") -> 0 | G7: =IFERROR(__xludf.DUMMYFUNCTION("COUNTA(UNIQUE(FILTER('Expression of Interest'!M:M, 'Expression of Interest'!H:H=$A7, 'Expression of Interest'!AA:AA=""Yes"")))"),1.0) -> 1 | H7: =COUNTIFS('Expression of Interest'!H:H, $A7, 'Expression of Interest'!F:F, "Yes") -> 0 | N7: =COUNTIFS('Expression of Interest'!M:M, $M7) -> 0 | O7: =N7/$N$14 -> #DIV/0!
A8: Italy | B8: =COUNTIF(DataBase!$B$2:$B$26,A8) > 0 -> FALSE | C8: =COUNTIFS('Expression of Interest'!H:H, A8, 'Expression of Interest'!AA:AA, "Yes") -> 0 | D8: =COUNTIFS('Expression of Interest'!H:H, $A8, 'Expression of Interest'!G:G, "F", 'Expression of Interest'!AA:AA, "Yes") -> 0 | E8: =COUNTIFS('Expression of Interest'!H:H, $A8, 'Expression of Interest'!J:J, "Yes", 'Expression of Interest'!AA:AA, "Yes") -> 0 | F8: =COUNTIFS('Expression of Interest'!H:H, $A8, 'Expression of Interest'!K:K, "Yes", 'Expression of Interest'!AA:AA, "Yes") -> 0 | G8: =IFERROR(__xludf.DUMMYFUNCTION("COUNTA(UNIQUE(FILTER('Expression of Interest'!M:M, 'Expression of Interest'!H:H=$A8, 'Expression of Interest'!AA:AA=""Yes"")))"),1.0) -> 1 | H8: =COUNTIFS('Expression of Interest'!H:H, $A8, 'Expression of Interest'!F:F, "Yes") -> 0 | N8: =COUNTIFS('Expression of Interest'!M:M, $M8) -> 0 | O8: =N8/$N$14 -> #DIV/0!
A9: Spain | B9: =COUNTIF(DataBase!$B$2:$B$26,A9) > 0 -> FALSE | C9: =COUNTIFS('Expression of Interest'!H:H, A9, 'Expression of Interest'!AA:AA, "Yes") -> 0 | D9: =COUNTIFS('Expression of Interest'!H:H, $A9, 'Expression of Interest'!G:G, "F", 'Expression of Interest'!AA:AA, "Yes") -> 0 | E9: =COUNTIFS('Expression of Interest'!H:H, $A9, 'Expression of Interest'!J:J, "Yes", 'Expression of Interest'!AA:AA, "Yes") -> 0 | F9: =COUNTIFS('Expression of Interest'!H:H, $A9, 'Expression of Interest'!K:K, "Yes", 'Expression of Interest'!AA:AA, "Yes") -> 0 | G9: =IFERROR(__xludf.DUMMYFUNCTION("COUNTA(UNIQUE(FILTER('Expression of Interest'!M:M, 'Expression of Interest'!H:H=$A9, 'Expression of Interest'!AA:AA=""Yes"")))"),1.0) -> 1 | H9: =COUNTIFS('Expression of Interest'!H:H, $A9, 'Expression of Interest'!F:F, "Yes") -> 0 | J9: Would be nice to include Luis but we cannot get the macros right if we do that | N9: =COUNTIFS('Expression of Interest'!M:M, $M9) -> 0 | O9: =N9/$N$14 -> #DIV/0!
A10: Greece | B10: =COUNTIF(DataBase!$B$2:$B$26,A10) > 0 -> TRUE | C10: =COUNTIFS('Expression of Interest'!H:H, A10, 'Expression of Interest'!AA:AA, "Yes") -> 0 | D10: =COUNTIFS('Expression of Interest'!H:H, $A10, 'Expression of Interest'!G:G, "F", 'Expression of Interest'!AA:AA, "Yes") -> 0 | E10: =COUNTIFS('Expression of Interest'!H:H, $A10, 'Expression of Interest'!J:J, "Yes", 'Expression of Interest'!AA:AA, "Yes") -> 0 | F10: =COUNTIFS('Expression of Interest'!H:H, $A10, 'Expression of Interest'!K:K, "Yes", 'Expression of Interest'!AA:AA, "Yes") -> 0 | G10: =IFERROR(__xludf.DUMMYFUNCTION("COUNTA(UNIQUE(FILTER('Expression of Interest'!M:M, 'Expression of Interest'!H:H=$A10, 'Expression of Interest'!AA:AA=""Yes"")))"),1.0) -> 1 | H10: =COUNTIFS('Expression of Interest'!H:H, $A10, 'Expression of Interest'!F:F, "Yes") -> 0 | J10: Very scattered accross institutions | N10: =COUNTIFS('Expression of Interest'!M:M, $M10) -> 0 | O10: =N10/$N$14 -> #DIV/0!
A11: United Kingdom | B11: =COUNTIF(DataBase!$B$2:$B$26,A11) > 0 -> FALSE | C11: =COUNTIFS('Expression of Interest'!H:H, A11, 'Expression of Interest'!AA:AA, "Yes") -> 0 | D11: =COUNTIFS('Expression of Interest'!H:H, $A11, 'Expression of Interest'!G:G, "F", 'Expression of Interest'!AA:AA, "Yes") -> 0 | E11: =COUNTIFS('Expression of Interest'!H:H, $A11, 'Expression of Interest'!J:J, "Yes", 'Expression of Interest'!AA:AA, "Yes") -> 0 | F11: =COUNTIFS('Expression of Interest'!H:H, $A11, 'Expression of Interest'!K:K, "Yes", 'Expression of Interest'!AA:AA, "Yes") -> 0 | G11: =IFERROR(__xludf.DUMMYFUNCTION("COUNTA(UNIQUE(FILTER('Expression of Interest'!M:M, 'Expression of Interest'!H:H=$A11, 'Expression of Interest'!AA:AA=""Yes"")))"),1.0) -> 1 | H11: =COUNTIFS('Expression of Interest'!H:H, $A11, 'Expression of Interest'!F:F, "Yes") -> 0 | I11: 45573 | J11: Only one person from oxford, need one more from industry | N11: =COUNTIFS('Expression of Interest'!M:M, $M11) -> 0 | O11: =N11/$N$14 -> #DIV/0!
A12: The Republic of North Macedonia | B12: =COUNTIF(DataBase!$B$2:$B$26,A12) > 0 -> TRUE | C12: =COUNTIFS('Expression of Interest'!H:H, A12, 'Expression of Interest'!AA:AA, "Yes") -> 0 | D12: =COUNTIFS('Expression of Interest'!H:H, $A12, 'Expression of Interest'!G:G, "F", 'Expression of Interest'!AA:AA, "Yes") -> 0 | E12: =COUNTIFS('Expression of Interest'!H:H, $A12, 'Expression of Interest'!J:J, "Yes", 'Expression of Interest'!AA:AA, "Yes") -> 0 | F12: =COUNTIFS('Expression of Interest'!H:H, $A12, 'Expression of Interest'!K:K, "Yes", 'Expression of Interest'!AA:AA, "Yes") -> 0 | G12: =IFERROR(__xludf.DUMMYFUNCTION("COUNTA(UNIQUE(FILTER('Expression of Interest'!M:M, 'Expression of Interest'!H:H=$A12, 'Expression of Interest'!AA:AA=""Yes"")))"),1.0) -> 1 | H12: =COUNTIFS('Expression of Interest'!H:H, $A12, 'Expression of Interest'!F:F, "Yes") -> 0 | J12: 3 unis | N12: =COUNTIFS('Expression of Interest'!M:M, $M12) -> 0 | O12: =N12/$N$14 -> #DIV/0!
A13: Croatia | B13: =COUNTIF(DataBase!$B$2:$B$26,A13) > 0 -> TRUE | C13: =COUNTIFS('Expression of Interest'!H:H, A13, 'Expression of Interest'!AA:AA, "Yes") -> 0 | D13: =COUNTIFS('Expression of Interest'!H:H, $A13, 'Expression of Interest'!G:G, "F", 'Expression of Interest'!AA:AA, "Yes") -> 0 | E13: =COUNTIFS('Expression of Interest'!H:H, $A13, 'Expression of Interest'!J:J, "Yes", 'Expression of Interest'!AA:AA, "Yes") -> 0 | F13: =COUNTIFS('Expression of Interest'!H:H, $A13, 'Expression of Interest'!K:K, "Yes", 'Expression of Interest'!AA:AA, "Yes") -> 0 | G13: =IFERROR(__xludf.DUMMYFUNCTION("COUNTA(UNIQUE(FILTER('Expression of Interest'!M:M, 'Expression of Interest'!H:H=$A13, 'Expression of Interest'!AA:AA=""Yes"")))"),1.0) -> 1 | H13: =COUNTIFS('Expression of Interest'!H:H, $A13, 'Expression of Interest'!F:F, "Yes") -> 0 | J13: Deadline 24th | N13: =COUNTIFS('Expression of Interest'!M:M, $M13) -> 0 | O13: =N13/$N$14 -> #DIV/0!
A14: Kosovo | B14: =COUNTIF(DataBase!$B$2:$B$26,A14) > 0 -> FALSE | C14: =COUNTIFS('Expression of Interest'!H:H, A14, 'Expression of Interest'!AA:AA, "Yes") -> 0 | D14: =COUNTIFS('Expression of Interest'!H:H, $A14, 'Expression of Interest'!G:G, "F", 'Expression of Interest'!AA:AA, "Yes") -> 0 | E14: =COUNTIFS('Expression of Interest'!H:H, $A14, 'Expression of Interest'!J:J, "Yes", 'Expression of Interest'!AA:AA, "Yes") -> 0 | F14: =COUNTIFS('Expression of Interest'!H:H, $A14, 'Expression of Interest'!K:K, "Yes", 'Expression of Interest'!AA:AA, "Yes") -> 0 | G14: =IFERROR(__xludf.DUMMYFUNCTION("COUNTA(UNIQUE(FILTER('Expression of Interest'!M:M, 'Expression of Interest'!H:H=$A14, 'Expression of Interest'!AA:AA=""Yes"")))"),1.0) -> 1 | H14: =COUNTIFS('Expression of Interest'!H:H, $A14, 'Expression of Interest'!F:F, "Yes") -> 0 | N14: =SUM(N3:N13) -> 0
A15: Albania | B15: =COUNTIF(DataBase!$B$2:$B$26,A15) > 0 -> TRUE | C15: =COUNTIFS('Expression of Interest'!H:H, A15, 'Expression of Interest'!AA:AA, "Yes") -> 0 | D15: =COUNTIFS('Expression of Interest'!H:H, $A15, 'Expression of Interest'!G:G, "F", 'Expression of Interest'!AA:AA, "Yes") -> 0 | E15: =COUNTIFS('Expression of Interest'!H:H, $A15, 'Expression of Interest'!J:J, "Yes", 'Expression of Interest'!AA:AA, "Yes") -> 0 | F15: =COUNTIFS('Expression of Interest'!H:H, $A15, 'Expression of Interest'!K:K, "Yes", 'Expression of Interest'!AA:AA, "Yes") -> 0 | G15: =IFERROR(__xludf.DUMMYFUNCTION("COUNTA(UNIQUE(FILTER('Expression of Interest'!M:M, 'Expression of Interest'!H:H=$A15, 'Expression of Interest'!AA:AA=""Yes"")))"),1.0) -> 1 | H15: =COUNTIFS('Expression of Interest'!H:H, $A15, 'Expression of Interest'!F:F, "Yes") -> 0
A16: Hungary | B16: =COUNTIF(DataBase!$B$2:$B$26,A16) > 0 -> TRUE | C16: =COUNTIFS('Expression of Interest'!H:H, A16, 'Expression of Interest'!AA:AA, "Yes") -> 0 | D16: =COUNTIFS('Expression of Interest'!H:H, $A16, 'Expression of Interest'!G:G, "F", 'Expression of Interest'!AA:AA, "Yes") -> 0 | E16: =COUNTIFS('Expression of Interest'!H:H, $A16, 'Expression of Interest'!J:J, "Yes", 'Expression of Interest'!AA:AA, "Yes") -> 0 | F16: =COUNTIFS('Expression of Interest'!H:H, $A16, 'Expression of Interest'!K:K, "Yes", 'Expression of Interest'!AA:AA, "Yes") -> 0 | G16: =IFERROR(__xludf.DUMMYFUNCTION("COUNTA(UNIQUE(FILTER('Expression of Interest'!M:M, 'Expression of Interest'!H:H=$A16, 'Expression of Interest'!AA:AA=""Yes"")))"),1.0) -> 1 | H16: =COUNTIFS('Expression of Interest'!H:H, $A16, 'Expression of Interest'!F:F, "Yes") -> 0 | J16: 5 from 1 uni, otherwise we cannot get the macros right
A17: Serbia | B17: =COUNTIF(DataBase!$B$2:$B$26,A17) > 0 -> TRUE | C17: =COUNTIFS('Expression of Interest'!H:H, A17, 'Expression of Interest'!AA:AA, "Yes") -> 0 | D17: =COUNTIFS('Expression of Interest'!H:H, $A17, 'Expression of Interest'!G:G, "F", 'Expression of Interest'!AA:AA, "Yes") -> 0 | E17: =COUNTIFS('Expression of Interest'!H:H, $A17, 'Expression of Interest'!J:J, "Yes", 'Expression of Interest'!AA:AA, "Yes") -> 0 | F17: =COUNTIFS('Expression of Interest'!H:H, $A17, 'Expression of Interest'!K:K, "Yes", 'Expression of Interest'!AA:AA, "Yes") -> 0 | G17: =IFERROR(__xludf.DUMMYFUNCTION("COUNTA(UNIQUE(FILTER('Expression of Interest'!M:M, 'Expression of Interest'!H:H=$A17, 'Expression of Interest'!AA:AA=""Yes"")))"),1.0) -> 1 | H17: =COUNTIFS('Expression of Interest'!H:H, $A17, 'Expression of Interest'!F:F, "Yes") -> 0
A18: Poland | B18: =COUNTIF(DataBase!$B$2:$B$26,A18) > 0 -> TRUE | C18: =COUNTIFS('Expression of Interest'!H:H, A18, 'Expression of Interest'!AA:AA, "Yes") -> 0 | D18: =COUNTIFS('Expression of Interest'!H:H, $A18, 'Expression of Interest'!G:G, "F", 'Expression of Interest'!AA:AA, "Yes") -> 0 | E18: =COUNTIFS('Expression of Interest'!H:H, $A18, 'Expression of Interest'!J:J, "Yes", 'Expression of Interest'!AA:AA, "Yes") -> 0 | F18: =COUNTIFS('Expression of Interest'!H:H, $A18, 'Expression of Interest'!K:K, "Yes", 'Expression of Interest'!AA:AA, "Yes") -> 0 | G18: =IFERROR(__xludf.DUMMYFUNCTION("COUNTA(UNIQUE(FILTER('Expression of Interest'!M:M, 'Expression of Interest'!H:H=$A18, 'Expression of Interest'!AA:AA=""Yes"")))"),1.0) -> 1 | H18: =COUNTIFS('Expression of Interest'!H:H, $A18, 'Expression of Interest'!F:F, "Yes") -> 0 | M18: COST countries without applicants
A19: Romania | B19: =COUNTIF(DataBase!$B$2:$B$26,A19) > 0 -> TRUE | C19: =COUNTIFS('Expression of Interest'!H:H, A19, 'Expression of Interest'!AA:AA, "Yes") -> 0 | D19: =COUNTIFS('Expression of Interest'!H:H, $A19, 'Expression of Interest'!G:G, "F", 'Expression of Interest'!AA:AA, "Yes") -> 0 | E19: =COUNTIFS('Expression of Interest'!H:H, $A19, 'Expression of Interest'!J:J, "Yes", 'Expression of Interest'!AA:AA, "Yes") -> 0 | F19: =COUNTIFS('Expression of Interest'!H:H, $A19, 'Expression of Interest'!K:K, "Yes", 'Expression of Interest'!AA:AA, "Yes") -> 0 | G19: =IFERROR(__xludf.DUMMYFUNCTION("COUNTA(UNIQUE(FILTER('Expression of Interest'!M:M, 'Expression of Interest'!H:H=$A19, 'Expression of Interest'!AA:AA=""Yes"")))"),1.0) -> 1 | H19: =COUNTIFS('Expression of Interest'!H:H, $A19, 'Expression of Interest'!F:F, "Yes") -> 0 | J19: 3 unis | M19: =IFERROR(__xludf.DUMMYFUNCTION("FILTER(DataBase!A2:A42, ISNA(MATCH(DataBase!A2:A42, A3:A45, 0))) "),"Armenia") -> Armenia | N19: Martin will try
A20: Lithuania | B20: =COUNTIF(DataBase!$B$2:$B$26,A20) > 0 -> TRUE | C20: =COUNTIFS('Expression of Interest'!H:H, A20, 'Expression of Interest'!AA:AA, "Yes") -> 0 | D20: =COUNTIFS('Expression of Interest'!H:H, $A20, 'Expression of Interest'!G:G, "F", 'Expression of Interest'!AA:AA, "Yes") -> 0 | E20: =COUNTIFS('Expression of Interest'!H:H, $A20, 'Expression of Interest'!J:J, "Yes", 'Expression of Interest'!AA:AA, "Yes") -> 0 | F20: =COUNTIFS('Expression of Interest'!H:H, $A20, 'Expression of Interest'!K:K, "Yes", 'Expression of Interest'!AA:AA, "Yes") -> 0 | G20: =IFERROR(__xludf.DUMMYFUNCTION("COUNTA(UNIQUE(FILTER('Expression of Interest'!M:M, 'Expression of Interest'!H:H=$A20, 'Expression of Interest'!AA:AA=""Yes"")))"),1.0) -> 1 | H20: =COUNTIFS('Expression of Interest'!H:H, $A20, 'Expression of Interest'!F:F, "Yes") -> 0 | J20: Invite to portal | M20: =IFERROR(__xludf.DUMMYFUNCTION("""COMPUTED_VALUE"""),"Belgium") -> Belgium | N20: Martin will try
A21: The Netherlands | B21: =COUNTIF(DataBase!$B$2:$B$26,A21) > 0 -> FALSE | C21: =COUNTIFS('Expression of Interest'!H:H, A21, 'Expression of Interest'!AA:AA, "Yes") -> 0 | D21: =COUNTIFS('Expression of Interest'!H:H, $A21, 'Expression of Interest'!G:G, "F", 'Expression of Interest'!AA:AA, "Yes") -> 0 | E21: =COUNTIFS('Expression of Interest'!H:H, $A21, 'Expression of Interest'!J:J, "Yes", 'Expression of Interest'!AA:AA, "Yes") -> 0 | F21: =COUNTIFS('Expression of Interest'!H:H, $A21, 'Expression of Interest'!K:K, "Yes", 'Expression of Interest'!AA:AA, "Yes") -> 0 | G21: =IFERROR(__xludf.DUMMYFUNCTION("COUNTA(UNIQUE(FILTER('Expression of Interest'!M:M, 'Expression of Interest'!H:H=$A21, 'Expression of Interest'!AA:AA=""Yes"")))"),1.0) -> 1 | H21: =COUNTIFS('Expression of Interest'!H:H, $A21, 'Expression of Interest'!F:F, "Yes") -> 0 | I21: NA | J21: Ask joerg | M21: =IFERROR(__xludf.DUMMYFUNCTION("""COMPUTED_VALUE"""),"Georgia") -> Georgia | N21: Petr and David are both working on this
A22: Malta | B22: =COUNTIF(DataBase!$B$2:$B$26,A22) > 0 -> TRUE | C22: =COUNTIFS('Expression of Interest'!H:H, A22, 'Expression of Interest'!AA:AA, "Yes") -> 0 | D22: =COUNTIFS('Expression of Interest'!H:H, $A22, 'Expression of Interest'!G:G, "F", 'Expression of Interest'!AA:AA, "Yes") -> 0 | E22: =COUNTIFS('Expression of Interest'!H:H, $A22, 'Expression of Interest'!J:J, "Yes", 'Expression of Interest'!AA:AA, "Yes") -> 0 | F22: =COUNTIFS('Expression of Interest'!H:H, $A22, 'Expression of Interest'!K:K, "Yes", 'Expression of Interest'!AA:AA, "Yes") -> 0 | G22: =IFERROR(__xludf.DUMMYFUNCTION("COUNTA(UNIQUE(FILTER('Expression of Interest'!M:M, 'Expression of Interest'!H:H=$A22, 'Expression of Interest'!AA:AA=""Yes"")))"),1.0) -> 1 | H22: =COUNTIFS('Expression of Interest'!H:H, $A22, 'Expression of Interest'!F:F, "Yes") -> 0 | I22: 45573 | J22: Send email to new researcher for missing | M22: Israel
A23: Switzerland | B23: =COUNTIF(DataBase!$B$2:$B$26,A23) > 0 -> FALSE | C23: =COUNTIFS('Expression of Interest'!H:H, A23, 'Expression of Interest'!AA:AA, "Yes") -> 0 | D23: =COUNTIFS('Expression of Interest'!H:H, $A23, 'Expression of Interest'!G:G, "F", 'Expression of Interest'!AA:AA, "Yes") -> 0 | E23: =COUNTIFS('Expression of Interest'!H:H, $A23, 'Expression of Interest'!J:J, "Yes", 'Expression of Interest'!AA:AA, "Yes") -> 0 | F23: =COUNTIFS('Expression of Interest'!H:H, $A23, 'Expression of Interest'!K:K, "Yes", 'Expression of Interest'!AA:AA, "Yes") -> 0 | G23: =IFERROR(__xludf.DUMMYFUNCTION("COUNTA(UNIQUE(FILTER('Expression of Interest'!M:M, 'Expression of Interest'!H:H=$A23, 'Expression of Interest'!AA:AA=""Yes"")))"),1.0) -> 1 | H23: =COUNTIFS('Expression of Interest'!H:H, $A23, 'Expression of Interest'!F:F, "Yes") -> 0 | I23: NA | J23: Ask joerg | M23: South Africa | N23: Martin will try
A24: Czech Republic | B24: =COUNTIF(DataBase!$B$2:$B$26,A24) > 0 -> FALSE | C24: =COUNTIFS('Expression of Interest'!H:H, A24, 'Expression of Interest'!AA:AA, "Yes") -> 0 | D24: =COUNTIFS('Expression of Interest'!H:H, $A24, 'Expression of Interest'!G:G, "F", 'Expression of Interest'!AA:AA, "Yes") -> 0 | E24: =COUNTIFS('Expression of Interest'!H:H, $A24, 'Expression of Interest'!J:J, "Yes", 'Expression of Interest'!AA:AA, "Yes") -> 0 | F24: =COUNTIFS('Expression of Interest'!H:H, $A24, 'Expression of Interest'!K:K, "Yes", 'Expression of Interest'!AA:AA, "Yes") -> 0 | G24: =IFERROR(__xludf.DUMMYFUNCTION("COUNTA(UNIQUE(FILTER('Expression of Interest'!M:M, 'Expression of Interest'!H:H=$A24, 'Expression of Interest'!AA:AA=""Yes"")))"),1.0) -> 1 | H24: =COUNTIFS('Expression of Interest'!H:H, $A24, 'Expression of Interest'!F:F, "Yes") -> 0 | M24: Austria | N24: Martin will try
A25: Iceland | B25: =COUNTIF(DataBase!$B$2:$B$26,A25) > 0 -> FALSE | C25: =COUNTIFS('Expression of Interest'!H:H, A25, 'Expression of Interest'!AA:AA, "Yes") -> 0 | D25: =COUNTIFS('Expression of Interest'!H:H, $A25, 'Expression of Interest'!G:G, "F", 'Expression of Interest'!AA:AA, "Yes") -> 0 | E25: =COUNTIFS('Expression of Interest'!H:H, $A25, 'Expression of Interest'!J:J, "Yes", 'Expression of Interest'!AA:AA, "Yes") -> 0 | F25: =COUNTIFS('Expression of Interest'!H:H, $A25, 'Expression of Interest'!K:K, "Yes", 'Expression of Interest'!AA:AA, "Yes") -> 0 | G25: =IFERROR(__xludf.DUMMYFUNCTION("COUNTA(UNIQUE(FILTER('Expression of Interest'!M:M, 'Expression of Interest'!H:H=$A25, 'Expression of Interest'!AA:AA=""Yes"")))"),1.0) -> 1 | H25: =COUNTIFS('Expression of Interest'!H:H, $A25, 'Expression of Interest'!F:F, "Yes") -> 0 | I25: NA | J25: Ask joerg | M25: Germany
A26: Vietnam | B26: =COUNTIF(DataBase!$B$2:$B$26,A26) > 0 -> FALSE | C26: =COUNTIFS('Expression of Interest'!H:H, A26, 'Expression of Interest'!AA:AA, "Yes") -> 0 | D26: =COUNTIFS('Expression of Interest'!H:H, $A26, 'Expression of Interest'!G:G, "F", 'Expression of Interest'!AA:AA, "Yes") -> 0 | E26: =COUNTIFS('Expression of Interest'!H:H, $A26, 'Expression of Interest'!J:J, "Yes", 'Expression of Interest'!AA:AA, "Yes") -> 0 | F26: =COUNTIFS('Expression of Interest'!H:H, $A26, 'Expression of Interest'!K:K, "Yes", 'Expression of Interest'!AA:AA, "Yes") -> 0 | G26: =IFERROR(__xludf.DUMMYFUNCTION("COUNTA(UNIQUE(FILTER('Expression of Interest'!M:M, 'Expression of Interest'!H:H=$A26, 'Expression of Interest'!AA:AA=""Yes"")))"),1.0) -> 1 | H26: =COUNTIFS('Expression of Interest'!H:H, $A26, 'Expression of Interest'!F:F, "Yes") -> 0 | I26: 45561 | J26: Industry and fields lacking, is this a problem? | M26: Sweden
A27: Cyprus | B27: =COUNTIF(DataBase!$B$2:$B$26,A27) > 0 -> TRUE | C27: =COUNTIFS('Expression of Interest'!H:H, A27, 'Expression of Interest'!AA:AA, "Yes") -> 0 | D27: =COUNTIFS('Expression of Interest'!H:H, $A27, 'Expression of Interest'!G:G, "F", 'Expression of Interest'!AA:AA, "Yes") -> 0 | E27: =COUNTIFS('Expression of Interest'!H:H, $A27, 'Expression of Interest'!J:J, "Yes", 'Expression of Interest'!AA:AA, "Yes") -> 0 | F27: =COUNTIFS('Expression of Interest'!H:H, $A27, 'Expression of Interest'!K:K, "Yes", 'Expression of Interest'!AA:AA, "Yes") -> 0 | G27: =IFERROR(__xludf.DUMMYFUNCTION("COUNTA(UNIQUE(FILTER('Expression of Interest'!M:M, 'Expression of Interest'!H:H=$A27, 'Expression of Interest'!AA:AA=""Yes"")))"),1.0) -> 1 | H27: =COUNTIFS('Expression of Interest'!H:H, $A27, 'Expression of Interest'!F:F, "Yes") -> 0 | I27: NA | J27: Dead end ,fine | M27: Luxembourg
A28: Estonia | B28: =COUNTIF(DataBase!$B$2:$B$26,A28) > 0 -> TRUE | C28: =COUNTIFS('Expression of Interest'!H:H, A28, 'Expression of Interest'!AA:AA, "Yes") -> 0 | D28: =COUNTIFS('Expression of Interest'!H:H, $A28, 'Expression of Interest'!G:G, "F", 'Expression of Interest'!AA:AA, "Yes") -> 0 | E28: =COUNTIFS('Expression of Interest'!H:H, $A28, 'Expression of Interest'!J:J, "Yes", 'Expression of Interest'!AA:AA, "Yes") -> 0 | F28: =COUNTIFS('Expression of Interest'!H:H, $A28, 'Expression of Interest'!K:K, "Yes", 'Expression of Interest'!AA:AA, "Yes") -> 0 | G28: =IFERROR(__xludf.DUMMYFUNCTION("COUNTA(UNIQUE(FILTER('Expression of Interest'!M:M, 'Expression of Interest'!H:H=$A28, 'Expression of Interest'!AA:AA=""Yes"")))"),1.0) -> 1 | H28: =COUNTIFS('Expression of Interest'!H:H, $A28, 'Expression of Interest'!F:F, "Yes") -> 0 | I28: NA | J28: Sent reminder no5 at 4.10 with specific requirements | M28: South Korea | N28: Martin will try
A29: Germany | B29: =COUNTIF(DataBase!$B$2:$B$26,A29) > 0 -> FALSE | C29: =COUNTIFS('Expression of Interest'!H:H, A29, 'Expression of Interest'!AA:AA, "Yes") -> 0 | D29: =COUNTIFS('Expression of Interest'!H:H, $A29, 'Expression of Interest'!G:G, "F", 'Expression of Interest'!AA:AA, "Yes") -> 0 | E29: =COUNTIFS('Expression of Interest'!H:H, $A29, 'Expression of Interest'!J:J, "Yes", 'Expression of Interest'!AA:AA, "Yes") -> 0 | F29: =COUNTIFS('Expression of Interest'!H:H, $A29, 'Expression of Interest'!K:K, "Yes", 'Expression of Interest'!AA:AA, "Yes") -> 0 | G29: =IFERROR(__xludf.DUMMYFUNCTION("COUNTA(UNIQUE(FILTER('Expression of Interest'!M:M, 'Expression of Interest'!H:H=$A29, 'Expression of Interest'!AA:AA=""Yes"")))"),1.0) -> 1 | H29: =COUNTIFS('Expression of Interest'!H:H, $A29, 'Expression of Interest'!F:F, "Yes") -> 0 | I29: NA | J29: Ask joerg
A30: France | B30: =COUNTIF(DataBase!$B$2:$B$26,A30) > 0 -> FALSE | C30: =COUNTIFS('Expression of Interest'!H:H, A30, 'Expression of Interest'!AA:AA, "Yes") -> 0 | D30: =COUNTIFS('Expression of Interest'!H:H, $A30, 'Expression of Interest'!G:G, "F", 'Expression of Interest'!AA:AA, "Yes") -> 0 | E30: =COUNTIFS('Expression of Interest'!H:H, $A30, 'Expression of Interest'!J:J, "Yes", 'Expression of Interest'!AA:AA, "Yes") -> 0 | F30: =COUNTIFS('Expression of Interest'!H:H, $A30, 'Expression of Interest'!K:K, "Yes", 'Expression of Interest'!AA:AA, "Yes") -> 0 | G30: =IFERROR(__xludf.DUMMYFUNCTION("COUNTA(UNIQUE(FILTER('Expression of Interest'!M:M, 'Expression of Interest'!H:H=$A30, 'Expression of Interest'!AA:AA=""Yes"")))"),1.0) -> 1 | H30: =COUNTIFS('Expression of Interest'!H:H, $A30, 'Expression of Interest'!F:F, "Yes") -> 0
A31: Austria | B31: =COUNTIF(DataBase!$B$2:$B$26,A31) > 0 -> FALSE | C31: =COUNTIFS('Expression of Interest'!H:H, A31, 'Expression of Interest'!AA:AA, "Yes") -> 0 | D31: =COUNTIFS('Expression of Interest'!H:H, $A31, 'Expression of Interest'!G:G, "F", 'Expression of Interest'!AA:AA, "Yes") -> 0 | E31: =COUNTIFS('Expression of Interest'!H:H, $A31, 'Expression of Interest'!J:J, "Yes", 'Expression of Interest'!AA:AA, "Yes") -> 0 | F31: =COUNTIFS('Expression of Interest'!H:H, $A31, 'Expression of Interest'!K:K, "Yes", 'Expression of Interest'!AA:AA, "Yes") -> 0 | G31: =IFERROR(__xludf.DUMMYFUNCTION("COUNTA(UNIQUE(FILTER('Expression of Interest'!M:M, 'Expression of Interest'!H:H=$A31, 'Expression of Interest'!AA:AA=""Yes"")))"),1.0) -> 1 | H31: =COUNTIFS('Expression of Interest'!H:H, $A31, 'Expression of Interest'!F:F, "Yes") -> 0 | I31: 45573 | J31: Send email to new researchers for missing
A32: Bulgaria | B32: =COUNTIF(DataBase!$B$2:$B$26,A32) > 0 -> TRUE | C32: =COUNTIFS('Expression of Interest'!H:H, A32, 'Expression of Interest'!AA:AA, "Yes") -> 0 | D32: =COUNTIFS('Expression of Interest'!H:H, $A32, 'Expression of Interest'!G:G, "F", 'Expression of Interest'!AA:AA, "Yes") -> 0 | E32: =COUNTIFS('Expression of Interest'!H:H, $A32, 'Expression of Interest'!J:J, "Yes", 'Expression of Interest'!AA:AA, "Yes") -> 0 | F32: =COUNTIFS('Expression of Interest'!H:H, $A32, 'Expression of Interest'!K:K, "Yes", 'Expression of Interest'!AA:AA, "Yes") -> 0 | G32: =IFERROR(__xludf.DUMMYFUNCTION("COUNTA(UNIQUE(FILTER('Expression of Interest'!M:M, 'Expression of Interest'!H:H=$A32, 'Expression of Interest'!AA:AA=""Yes"")))"),1.0) -> 1 | H32: =COUNTIFS('Expression of Interest'!H:H, $A32, 'Expression of Interest'!F:F, "Yes") -> 0
